Workbook
Name Poles: 'WEG Motor'!$B$2:$C$2

Sheet Chilled Water Pump (349)
A1: S/N | B1: Rated Tonnage | C1: Flowrate (l/s) | D1: Head (m, calculation) | E1: Head (m, datasheet) | F1: Rated Power (kW, P2) | G1: Motor Input (kW, P1) (Pump + Motor) | H1: Overall Power Input (Pump + Motor + VSD) | I1: Pump Model | J1: Pump Model | K1: Motor Size (kW) | L1: Poles | M1: Motor Eff | N1: VSD Eff | O1: Pump Eff | P1: NPSHR (m) | Q1: Pump Power Limitation (kW/m3/s) | R1: SS553 Power Limitation (kW/m3/s) | S1: Price | T1: Remarks | U1: Motor Input (Calculation)
A2: 0 | C2: =ROUND((B2 * $AA$6 * 1000) / ($X$5*$AA$2*$AA$3),0) -> 0 | D2: =IFERROR(ROUNDUP((U2*$X$3*1000*$X$4*$X$2)/((C2/10^3)*$X$5*$AA$4),2),"") | F2: =((($X$5*$AA$4*(C2*0.001)*E2)/1000)/O2) -> #DIV/0! | G2: =F2/M2 -> #DIV/0! | H2: =G2/N2 -> #DIV/0! | I2: GIGA-I | M2: =INDEX('WEG Motor'!$B$3:$AZ$55, MATCH(K2,'WEG Motor'!$A$3:$A$55,0), MATCH(L2,'WEG Motor'!$B$2:$AZ$2,0))% -> #N/A | N2: 0.92 | Q2: =ROUNDUP(H2/(C2/10^3),2) -> #DIV/0! | R2: 349 | U2: =R2*(C2/10^3) -> 0 | W2: VSD | X2: 0.92 | Z2: △T | AA2: 7 | AC2: Rated Tonnage = Amount if heat needed to melt 1 ton of ice in 24 hrs
D3: =IFERROR(ROUNDUP((U3*$X$3*1000*$X$4*$X$2)/((C2/10^3)*$X$5*$AA$4),2),"") | F3: =((($X$5*$AA$4*(C2*0.001)*E3)/1000)/O3) -> #DIV/0! | G3: =F3/M3 -> #DIV/0! | H3: =G3/N3 -> #DIV/0! | I3: GIGA-B | M3: =INDEX('WEG Motor'!$B$3:$AZ$55, MATCH(K3,'WEG Motor'!$A$3:$A$55,0), MATCH(L3,'WEG Motor'!$B$2:$AZ$2,0))% -> #N/A | N3: 0.92 | Q3: =ROUNDUP(H3/(C2/10^3),2) -> #DIV/0! | U3: =R2*(C2/10^3) -> 0 | W3: Motor | X3: 0.94 | Z3: Specific Heat | AA3: 4.186
D4: =IFERROR(ROUNDUP((U4*$X$3*1000*$X$4*$X$2)/((C2/10^3)*$X$5*$AA$4),2),"") | F4: =((($X$5*$AA$4*(C2*0.001)*E4)/1000)/O4) -> #DIV/0! | G4: =F4/M4 -> #DIV/0! | H4: =G4/N4 -> #DIV/0! | I4: GIGA-N | M4: =INDEX('WEG Motor'!$B$3:$AZ$55, MATCH(K4,'WEG Motor'!$A$3:$A$55,0), MATCH(L4,'WEG Motor'!$B$2:$AZ$2,0))% -> #N/A | N4: 0.92 | Q4: =ROUNDUP(H4/(C2/10^3),2) -> #DIV/0! | U4: =R2*(C2/10^3) -> 0 | W4: Pump | X4: 0.8 | Z4: g | AA4: 9.81 | AC4: Pump Power limitation = Motor Input / Flowrate [m3/s]
D5: =IFERROR(ROUNDUP((U5*$X$3*1000*$X$4*$X$2)/((C2/10^3)*$X$5*$AA$4),2),"") | F5: =((($X$5*$AA$4*(C2*0.001)*E5)/1000)/O5) -> #DIV/0! | G5: =F5/M5 -> #DIV/0! | H5: =G5/N5 -> #DIV/0! | I5: GIGA-IC | M5: =INDEX('WEG Motor'!$B$3:$AZ$55, MATCH(K5,'WEG Motor'!$A$3:$A$55,0), MATCH(L5,'WEG Motor'!$B$2:$AZ$2,0))% -> #N/A | N5: 0.92 | Q5: =ROUNDUP(H5/(C2/10^3),2) -> #DIV/0! | U5: =R2*(C2/10^3) -> 0 | W5: Density | X5: 999.78 | Z5: RT | AA5: kW
D6: =IFERROR(ROUNDUP((U6*$X$3*1000*$X$4*$X$2)/((C2/10^3)*$X$5*$AA$4),2),"") | F6: =((($X$5*$AA$4*(C2*0.001)*E6)/1000)/O6) -> #DIV/0! | G6: =F6/M6 -> #DIV/0! | H6: =G6/N6 -> #DIV/0! | I6: SCP | M6: =INDEX('WEG Motor'!$B$3:$AZ$55, MATCH(K6,'WEG Motor'!$A$3:$A$55,0), MATCH(L6,'WEG Motor'!$B$2:$AZ$2,0))% -> #N/A | N6: 0.92 | Q6: =ROUNDUP(H6/(C2/10^3),2) -> #DIV/0! | U6: =R2*(C2/10^3) -> 0 | Z6: 1 | AA6: 3.517 | AC6: Rated Tonnage =( (Flowrate / 1000) * Density * Change in Temp * Specific Heat) / 3.517
D7: =IFERROR(ROUNDUP((U7*$X$3*1000*$X$4*$X$2)/((C2/10^3)*$X$5*$AA$4),2),"") | F7: =((($X$5*$AA$4*(C2*0.001)*E7)/1000)/O7) -> #DIV/0! | G7: =F7/M7 -> #DIV/0! | H7: =G7/N7 -> #DIV/0! | I7: SCP-V | M7: =INDEX('WEG Motor'!$B$3:$AZ$55, MATCH(K7,'WEG Motor'!$A$3:$A$55,0), MATCH(L7,'WEG Motor'!$B$2:$AZ$2,0))% -> #N/A | N7: 0.92 | Q7: =ROUNDUP(H7/(C2/10^3),2) -> #DIV/0! | U7: =R2*(C2/10^3) -> 0
A8: 1 | B8: 300 | C8: =ROUND((B8 * $AA$6 * 1000) / ($X$5*$AA$2*$AA$3),0) -> 36 | D8: =IFERROR(ROUNDUP((U8*$X$3*1000*$X$4*$X$2)/((C8/10^3)*$X$5*$AA$4),2),"") -> 24.62 | E8: 24 | F8: =((($X$5*$AA$4*(C8*0.001)*E8)/1000)/O8) -> 10.508402 | G8: =F8/M8 -> 11.409774 | H8: =G8/N8 -> 12.401928 | I8: GIGA-I | J8: Atmos GIGA-I 125/250-15/4-L1 EN | K8: 15 | L8: 4P | M8: =INDEX('WEG Motor'!$B$3:$AZ$55, MATCH(K8,'WEG Motor'!$A$3:$A$55,0), MATCH(L8,'WEG Motor'!$B$2:$AZ$2,0))% -> 0.921 | N8: 0.92 | O8: 0.8064 | P8: 1.692 | Q8: =ROUNDUP(H8/(C8/10^3),2) -> 344.5 | R8: 349 | U8: =R8*(C8/10^3) -> 12.564 | W8: VSD | X8: 0.92 | Z8: △T | AA8: 7 | AC8: Rated Tonnage = Amount if heat needed to melt 1 ton of ice in 24 hrs
D9: =IFERROR(ROUNDUP((U9*$X$3*1000*$X$4*$X$2)/((C8/10^3)*$X$5*$AA$4),2),"") -> 24.62 | E9: 25 | F9: =((($X$5*$AA$4*(C8*0.001)*E9)/1000)/O9) -> 10.529712 | G9: =F9/M9 -> 11.432912 | H9: =G9/N9 -> 12.427078 | I9: GIGA-B | J9: Atmos GIGA-B 100/250-15/4-L1-S | K9: 15 | L9: 4P | M9: =INDEX('WEG Motor'!$B$3:$AZ$55, MATCH(K9,'WEG Motor'!$A$3:$A$55,0), MATCH(L9,'WEG Motor'!$B$2:$AZ$2,0))% -> 0.921 | N9: 0.92 | O9: 0.8383 | P9: 1.789 | Q9: =ROUNDUP(H9/(C8/10^3),2) -> 345.2 | S9: Check Again. | U9: =R8*(C8/10^3) -> 12.564 | W9: Motor | X9: 0.94 | Z9: Specific Heat | AA9: 4.186
D10: =IFERROR(ROUNDUP((U10*$X$3*1000*$X$4*$X$2)/((C8/10^3)*$X$5*$AA$4),2),"") -> 24.62 | E10: 24 | F10: =((($X$5*$AA$4*(C8*0.001)*E10)/1000)/O10) -> 10.383501 | G10: =F10/M10 -> 11.27416 | H10: =G10/N10 -> 12.254522 | I10: GIGA-N | J10: Atmos GIGA-N 100/250-15/4-L1 | K10: 15 | L10: 4P | M10: =INDEX('WEG Motor'!$B$3:$AZ$55, MATCH(K10,'WEG Motor'!$A$3:$A$55,0), MATCH(L10,'WEG Motor'!$B$2:$AZ$2,0))% -> 0.921 | N10: 0.92 | O10: 0.8161 | P10: 1.865 | Q10: =ROUNDUP(H10/(C8/10^3),2) -> 340.41 | U10: =R8*(C8/10^3) -> 12.564 | W10: Pump | X10: 0.8 | Z10: g | AA10: 9.81 | AC10: Pump Power limitation = Motor Input / Flowrate [m3/s]
D11: =IFERROR(ROUNDUP((U11*$X$3*1000*$X$4*$X$2)/((C8/10^3)*$X$5*$AA$4),2),"") -> 24.62 | E11: 24 | F11: =((($X$5*$AA$4*(C8*0.001)*E11)/1000)/O11) -> 10.521449 | G11: =F11/M11 -> 11.423941 | H11: =G11/N11 -> 12.417327 | I11: GIGA-IC | J11: Atmos GIGA-IC 125/250-15/4-L1-GB3 | K11: 15 | L11: 4P | M11: =INDEX('WEG Motor'!$B$3:$AZ$55, MATCH(K11,'WEG Motor'!$A$3:$A$55,0), MATCH(L11,'WEG Motor'!$B$2:$AZ$2,0))% -> 0.921 | N11: 0.92 | O11: 0.8054 | P11: 1.727 | Q11: =ROUNDUP(H11/(C8/10^3),2) -> 344.93 | U11: =R8*(C8/10^3) -> 12.564 | W11: Density | X11: 999.78 | Z11: RT | AA11: kW
D12: =IFERROR(ROUNDUP((U12*$X$3*1000*$X$4*$X$2)/((C8/10^3)*$X$5*$AA$4),2),"") -> 24.62 | E12: 25 | F12: =((($X$5*$AA$4*(C8*0.001)*E12)/1000)/O12) -> 10.527201 | G12: =F12/M12 -> 11.430185 | H12: =G12/N12 -> 12.424114 | I12: SCP | J12: SCP-100-280-HA | K12: 15 | L12: 4P | M12: =INDEX('WEG Motor'!$B$3:$AZ$55, MATCH(K12,'WEG Motor'!$A$3:$A$55,0), MATCH(L12,'WEG Motor'!$B$2:$AZ$2,0))% -> 0.921 | N12: 0.92 | O12: 0.8385 | P12: 2.56 | Q12: =ROUNDUP(H12/(C8/10^3),2) -> 345.12 | T12: Pump offer is running at maximum impeller size. | U12: =R8*(C8/10^3) -> 12.564 | Z12: 1 | AA12: 3.517 | AC12: Rated Tonnage =( (Flowrate / 1000) * Density * Change in Temp * Specific Heat) / 3.517
D13: =IFERROR(ROUNDUP((U13*$X$3*1000*$X$4*$X$2)/((C8/10^3)*$X$5*$AA$4),2),"") -> 24.62 | E13: 25 | F13: =((($X$5*$AA$4*(C8*0.001)*E13)/1000)/O13) -> 10.527201 | G13: =F13/M13 -> 11.430185 | H13: =G13/N13 -> 12.424114 | I13: SCP-V | J13: SCPV-100-280-HA | K13: 15 | L13: 4P | M13: =INDEX('WEG Motor'!$B$3:$AZ$55, MATCH(K13,'WEG Motor'!$A$3:$A$55,0), MATCH(L13,'WEG Motor'!$B$2:$AZ$2,0))% -> 0.921 | N13: 0.92 | O13: 0.8385 | P13: 2.43 | Q13: =ROUNDUP(H13/(C8/10^3),2) -> 345.12 | T13: Pump offer is running at maximum impeller size. | U13: =R8*(C8/10^3) -> 12.564
A14: 2 | B14: 350 | C14: =ROUND((B14 * $AA$6 * 1000) / ($X$5*$AA$2*$AA$3),0) -> 42 | D14: =IFERROR(ROUNDUP((U14*$X$3*1000*$X$4*$X$2)/((C14/10^3)*$X$5*$AA$4),2),"") -> 24.62 | E14: 24.5 | F14: =((($X$5*$AA$4*(C14*0.001)*E14)/1000)/O14) -> 12.336229 | G14: =F14/M14 -> 13.394386 | H14: =G14/N14 -> 14.559115 | I14: GIGA-I | J14: Atmos GIGA-I 125/250-15/4-L1 EN | K14: 15 | L14: 4P | M14: =INDEX('WEG Motor'!$B$3:$AZ$55, MATCH(K14,'WEG Motor'!$A$3:$A$55,0), MATCH(L14,'WEG Motor'!$B$2:$AZ$2,0))% -> 0.921 | N14: 0.92 | O14: 0.8181 | P14: 2.04 | Q14: =ROUNDUP(H14/(C14/10^3),2) -> 346.65 | R14: 349 | U14: =R14*(C14/10^3) -> 14.658 | W14: VSD | X14: 0.92 | Z14: △T | AA14: 7 | AC14: Rated Tonnage = Amount if heat needed to melt 1 ton of ice in 24 hrs
D15: =IFERROR(ROUNDUP((U15*$X$3*1000*$X$4*$X$2)/((C14/10^3)*$X$5*$AA$4),2),"") -> 24.62 | E15: 25 | F15: =((($X$5*$AA$4*(C14*0.001)*E15)/1000)/O15) -> 12.232134 | G15: =F15/M15 -> 13.281362 | H15: =G15/N15 -> 14.436263 | I15: GIGA-B | J15: Atmos GIGA-B 100/250-15/4-L1 | K15: 15 | L15: 4P | M15: =INDEX('WEG Motor'!$B$3:$AZ$55, MATCH(K15,'WEG Motor'!$A$3:$A$55,0), MATCH(L15,'WEG Motor'!$B$2:$AZ$2,0))% -> 0.921 | N15: 0.92 | O15: 0.8419 | P15: 2.032 | Q15: =ROUNDUP(H15/(C14/10^3),2) -> 343.73 | U15: =R14*(C14/10^3) -> 14.658 | W15: Motor | X15: 0.94 | Z15: Specific Heat | AA15: 4.186
D16: =IFERROR(ROUNDUP((U16*$X$3*1000*$X$4*$X$2)/((C14/10^3)*$X$5*$AA$4),2),"") -> 24.62 | E16: 25.5 | F16: =((($X$5*$AA$4*(C14*0.001)*E16)/1000)/O16) -> 12.419246 | G16: =F16/M16 -> 13.484524 | H16: =G16/N16 -> 14.657091 | I16: GIGA-N | J16: Atmos GIGA-N 100/250-15/4-L1 | K16: 15 | L16: 4P | M16: =INDEX('WEG Motor'!$B$3:$AZ$55, MATCH(K16,'WEG Motor'!$A$3:$A$55,0), MATCH(L16,'WEG Motor'!$B$2:$AZ$2,0))% -> 0.921 | N16: 0.92 | O16: 0.8458 | P16: 2.032 | Q16: =ROUNDUP(H16/(C14/10^3),2) -> 348.98 | U16: =R14*(C14/10^3) -> 14.658 | W16: Pump | X16: 0.8 | Z16: g | AA16: 9.81 | AC16: Pump Power limitation = Motor Input / Flowrate [m3/s]
D17: =IFERROR(ROUNDUP((U17*$X$3*1000*$X$4*$X$2)/((C14/10^3)*$X$5*$AA$4),2),"") -> 24.62 | E17: 24.5 | F17: =((($X$5*$AA$4*(C14*0.001)*E17)/1000)/O17) -> 12.337737 | G17: =F17/M17 -> 13.396023 | H17: =G17/N17 -> 14.560895 | I17: GIGA-IC | J17: Atmos GIGA-IC 125/250-15/4-L1-GB3 | K17: 15 | L17: 4P | M17: =INDEX('WEG Motor'!$B$3:$AZ$55, MATCH(K17,'WEG Motor'!$A$3:$A$55,0), MATCH(L17,'WEG Motor'!$B$2:$AZ$2,0))% -> 0.921 | N17: 0.92 | O17: 0.818 | P17: 2.045 | Q17: =ROUNDUP(H17/(C14/10^3),2) -> 346.69 | U17: =R14*(C14/10^3) -> 14.658 | W17: Density | X17: 999.78 | Z17: RT | AA17: kW
D18: =IFERROR(ROUNDUP((U18*$X$3*1000*$X$4*$X$2)/((C14/10^3)*$X$5*$AA$4),2),"") -> 24.62 | E18: 24.5 | F18: =((($X$5*$AA$4*(C14*0.001)*E18)/1000)/O18) -> 12.090894 | G18: =F18/M18 -> 13.128007 | H18: =G18/N18 -> 14.269572 | I18: SCP | J18: SCP-100-280-HA | K18: 15 | L18: 4P | M18: =INDEX('WEG Motor'!$B$3:$AZ$55, MATCH(K18,'WEG Motor'!$A$3:$A$55,0), MATCH(L18,'WEG Motor'!$B$2:$AZ$2,0))% -> 0.921 | N18: 0.92 | O18: 0.8347 | P18: 2.57 | Q18: =ROUNDUP(H18/(C14/10^3),2) -> 339.76 | T18: Pump offer is running at maximum impeller size. | U18: =R14*(C14/10^3) -> 14.658 | Z18: 1 | AA18: 3.517 | AC18: Rated Tonnage =( (Flowrate / 1000) * Density * Change in Temp * Specific Heat) / 3.517
D19: =IFERROR(ROUNDUP((U19*$X$3*1000*$X$4*$X$2)/((C14/10^3)*$X$5*$AA$4),2),"") -> 24.62 | E19: 24.5 | F19: =((($X$5*$AA$4*(C14*0.001)*E19)/1000)/O19) -> 12.090894 | G19: =F19/M19 -> 13.128007 | H19: =G19/N19 -> 14.269572 | I19: SCP-V | J19: SCPV-100-280-HA | K19: 15 | L19: 4P | M19: =INDEX('WEG Motor'!$B$3:$AZ$55, MATCH(K19,'WEG Motor'!$A$3:$A$55,0), MATCH(L19,'WEG Motor'!$B$2:$AZ$2,0))% -> 0.921 | N19: 0.92 | O19: 0.8347 | P19: 2.57 | Q19: =ROUNDUP(H19/(C14/10^3),2) -> 339.76 | T19: Pump offer is running at maximum impeller size. | U19: =R14*(C14/10^3) -> 14.658
A20: 3 | B20: 400 | C20: =ROUND((B20 * $AA$6 * 1000) / ($X$5*$AA$2*$AA$3),0) -> 48 | D20: =IFERROR(ROUNDUP((U20*$X$3*1000*$X$4*$X$2)/((C20/10^3)*$X$5*$AA$4),2),"") -> 24.62 | E20: 24.5 | F20: =((($X$5*$AA$4*(C20*0.001)*E20)/1000)/O20) -> 14.016311 | G20: =F20/M20 -> 15.136404 | H20: =G20/N20 -> 16.452614 | I20: GIGA-I | J20: Atmos GIGA-I 150/275-18.5/4-L1 EN | K20: 18.5 | L20: 4P | M20: =INDEX('WEG Motor'!$B$3:$AZ$55, MATCH(K20,'WEG Motor'!$A$3:$A$55,0), MATCH(L20,'WEG Motor'!$B$2:$AZ$2,0))% -> 0.926 | N20: 0.92 | O20: 0.8229 | P20: 2.19 | Q20: =ROUNDUP(H20/(C20/10^3),2) -> 342.77 | R20: 349 | U20: =R20*(C20/10^3) -> 16.752 | W20: VSD | X20: 0.92 | Z20: △T | AA20: 7 | AC20: Rated Tonnage = Amount if heat needed to melt 1 ton of ice in 24 hrs
D21: =IFERROR(ROUNDUP((U21*$X$3*1000*$X$4*$X$2)/((C20/10^3)*$X$5*$AA$4),2),"") -> 24.62 | E21: 24.5 | F21: =((($X$5*$AA$4*(C20*0.001)*E21)/1000)/O21) -> 14.053883 | G21: =F21/M21 -> 15.17698 | H21: =G21/N21 -> 16.496717 | I21: GIGA-B | J21: Atmos GIGA-B 100/295-18.5/4-L1 | K21: 18.5 | L21: 4P | M21: =INDEX('WEG Motor'!$B$3:$AZ$55, MATCH(K21,'WEG Motor'!$A$3:$A$55,0), MATCH(L21,'WEG Motor'!$B$2:$AZ$2,0))% -> 0.926 | N21: 0.92 | O21: 0.8207 | P21: 2.638 | Q21: =ROUNDUP(H21/(C20/10^3),2) -> 343.69 | U21: =R20*(C20/10^3) -> 16.752 | W21: Motor | X21: 0.94 | Z21: Specific Heat | AA21: 4.186
D22: =IFERROR(ROUNDUP((U22*$X$3*1000*$X$4*$X$2)/((C20/10^3)*$X$5*$AA$4),2),"") -> 24.62 | E22: 24.5 | F22: =((($X$5*$AA$4*(C20*0.001)*E22)/1000)/O22) -> 14.053883 | G22: =F22/M22 -> 15.17698 | H22: =G22/N22 -> 16.496717 | I22: GIGA-N | J22: Atmos GIGA-N 100/315-18.5/4-L1 | K22: 18.5 | L22: 4P | M22: =INDEX('WEG Motor'!$B$3:$AZ$55, MATCH(K22,'WEG Motor'!$A$3:$A$55,0), MATCH(L22,'WEG Motor'!$B$2:$AZ$2,0))% -> 0.926 | N22: 0.92 | O22: 0.8207 | P22: 2.638 | Q22: =ROUNDUP(H22/(C20/10^3),2) -> 343.69 | U22: =R20*(C20/10^3) -> 16.752 | W22: Pump | X22: 0.8 | Z22: g | AA22: 9.81 | AC22: Pump Power limitation = Motor Input / Flowrate [m3/s]
D23: =IFERROR(ROUNDUP((U23*$X$3*1000*$X$4*$X$2)/((C20/10^3)*$X$5*$AA$4),2),"") -> 24.62 | E23: 24.5 | F23: =((($X$5*$AA$4*(C20*0.001)*E23)/1000)/O23) -> 14.264187 | G23: =F23/M23 -> 15.40409 | H23: =G23/N23 -> 16.743576 | I23: GIGA-IC | J23: Atmos GIGA-IC 150/250-18.5/4-L1-GB3 | K23: 18.5 | L23: 4P | M23: =INDEX('WEG Motor'!$B$3:$AZ$55, MATCH(K23,'WEG Motor'!$A$3:$A$55,0), MATCH(L23,'WEG Motor'!$B$2:$AZ$2,0))% -> 0.926 | N23: 0.92 | O23: 0.8086 | P23: 2.972 | Q23: =ROUNDUP(H23/(C20/10^3),2) -> 348.83 | U23: =R20*(C20/10^3) -> 16.752 | W23: Density | X23: 999.78 | Z23: RT | AA23: kW
D24: =IFERROR(ROUNDUP((U24*$X$3*1000*$X$4*$X$2)/((C20/10^3)*$X$5*$AA$4),2),"") -> 24.62 | E24: 24.5 | F24: =((($X$5*$AA$4*(C20*0.001)*E24)/1000)/O24) -> 13.980633 | G24: =F24/M24 -> 15.097875 | H24: =G24/N24 -> 16.410734 | I24: SCP | J24: SCP-125-290-HA | K24: 18.5 | L24: 4P | M24: =INDEX('WEG Motor'!$B$3:$AZ$55, MATCH(K24,'WEG Motor'!$A$3:$A$55,0), MATCH(L24,'WEG Motor'!$B$2:$AZ$2,0))% -> 0.926 | N24: 0.92 | O24: 0.825 | P24: 2.67 | Q24: =ROUNDUP(H24/(C20/10^3),2) -> 341.9 | T24: Pump offer is running at maximum impeller size. | U24: =R20*(C20/10^3) -> 16.752 | Z24: 1 | AA24: 3.517 | AC24: Rated Tonnage =( (Flowrate / 1000) * Density * Change in Temp * Specific Heat) / 3.517
D25: =IFERROR(ROUNDUP((U25*$X$3*1000*$X$4*$X$2)/((C20/10^3)*$X$5*$AA$4),2),"") -> 24.62 | E25: 24.5 | F25: =((($X$5*$AA$4*(C20*0.001)*E25)/1000)/O25) -> 13.980633 | G25: =F25/M25 -> 15.097875 | H25: =G25/N25 -> 16.410734 | I25: SCP-V | J25: SCPV-125-290-HA | K25: 18.5 | L25: 4P | M25: =INDEX('WEG Motor'!$B$3:$AZ$55, MATCH(K25,'WEG Motor'!$A$3:$A$55,0), MATCH(L25,'WEG Motor'!$B$2:$AZ$2,0))% -> 0.926 | N25: 0.92 | O25: 0.825 | P25: 2.67 | Q25: =ROUNDUP(H25/(C20/10^3),2) -> 341.9 | T25: Pump offer is running at maximum impeller size. | U25: =R20*(C20/10^3) -> 16.752
A26: 4 | B26: 450 | C26: =ROUND((B26 * $AA$6 * 1000) / ($X$5*$AA$2*$AA$3),0) -> 54 | D26: =IFERROR(ROUNDUP((U26*$X$3*1000*$X$4*$X$2)/((C26/10^3)*$X$5*$AA$4),2),"") -> 24.62 | E26: 24.5 | F26: =((($X$5*$AA$4*(C26*0.001)*E26)/1000)/O26) -> 15.526833 | G26: =F26/M26 -> 16.767639 | H26: =G26/N26 -> 18.225694 | I26: GIGA-I | J26: Atmos GIGA-I 150/275-18.5/4-L1 EN | K26: 18.5 | L26: 4P | M26: =INDEX('WEG Motor'!$B$3:$AZ$55, MATCH(K26,'WEG Motor'!$A$3:$A$55,0), MATCH(L26,'WEG Motor'!$B$2:$AZ$2,0))% -> 0.926 | N26: 0.92 | O26: 0.8357 | P26: 2.249 | Q26: =ROUNDUP(H26/(C26/10^3),2) -> 337.52 | R26: 349 | U26: =R26*(C26/10^3) -> 18.846 | W26: VSD | X26: 0.92 | Z26: △T | AA26: 7 | AC26: Rated Tonnage = Amount if heat needed to melt 1 ton of ice in 24 hrs
D27: =IFERROR(ROUNDUP((U27*$X$3*1000*$X$4*$X$2)/((C26/10^3)*$X$5*$AA$4),2),"") -> 24.62 | E27: 25 | F27: =((($X$5*$AA$4*(C26*0.001)*E27)/1000)/O27) -> 15.798337 | G27: =F27/M27 -> 17.060839 | H27: =G27/N27 -> 18.544391 | I27: GIGA-B | J27: Atmos GIGA-B 125/240-18.5/4-L1 | K27: 18.5 | L27: 4P | M27: =INDEX('WEG Motor'!$B$3:$AZ$55, MATCH(K27,'WEG Motor'!$A$3:$A$55,0), MATCH(L27,'WEG Motor'!$B$2:$AZ$2,0))% -> 0.926 | N27: 0.92 | O27: 0.8381 | P27: 2.567 | Q27: =ROUNDUP(H27/(C26/10^3),2) -> 343.42 | U27: =R26*(C26/10^3) -> 18.846 | W27: Motor | X27: 0.94 | Z27: Specific Heat | AA27: 4.186
D28: =IFERROR(ROUNDUP((U28*$X$3*1000*$X$4*$X$2)/((C26/10^3)*$X$5*$AA$4),2),"") -> 24.62 | E28: 24.5 | F28: =((($X$5*$AA$4*(C26*0.001)*E28)/1000)/O28) -> 15.897788 | G28: =F28/M28 -> 17.168238 | H28: =G28/N28 -> 18.661128 | I28: GIGA-N | J28: Atmos GIGA-N 125/315-18.5/4-L1 | K28: 18.5 | L28: 4P | M28: =INDEX('WEG Motor'!$B$3:$AZ$55, MATCH(K28,'WEG Motor'!$A$3:$A$55,0), MATCH(L28,'WEG Motor'!$B$2:$AZ$2,0))% -> 0.926 | N28: 0.92 | O28: 0.8162 | P28: 2.567 | Q28: =ROUNDUP(H28/(C26/10^3),2) -> 345.58 | U28: =R26*(C26/10^3) -> 18.846 | W28: Pump | X28: 0.8 | Z28: g | AA28: 9.81 | AC28: Pump Power limitation = Motor Input / Flowrate [m3/s]
D29: =IFERROR(ROUNDUP((U29*$X$3*1000*$X$4*$X$2)/((C26/10^3)*$X$5*$AA$4),2),"") -> 24.62 | E29: 25 | F29: =((($X$5*$AA$4*(C26*0.001)*E29)/1000)/O29) -> 15.858889 | G29: =F29/M29 -> 17.12623 | H29: =G29/N29 -> 18.615467 | I29: GIGA-IC | J29: Atmos GIGA-IC 150/315-18.5/4-L1-GB3 | K29: 18.5 | L29: 4P | M29: =INDEX('WEG Motor'!$B$3:$AZ$55, MATCH(K29,'WEG Motor'!$A$3:$A$55,0), MATCH(L29,'WEG Motor'!$B$2:$AZ$2,0))% -> 0.926 | N29: 0.92 | O29: 0.8349 | P29: 2.274 | Q29: =ROUNDUP(H29/(C26/10^3),2) -> 344.74 | U29: =R26*(C26/10^3) -> 18.846 | W29: Density | X29: 999.78 | Z29: RT | AA29: kW
D30: =IFERROR(ROUNDUP((U30*$X$3*1000*$X$4*$X$2)/((C26/10^3)*$X$5*$AA$4),2),"") -> 24.62 | E30: 24.5 | F30: =((($X$5*$AA$4*(C26*0.001)*E30)/1000)/O30) -> 16.02739 | G30: =F30/M30 -> 17.308196 | H30: =G30/N30 -> 18.813257 | I30: SCP | J30: SCP-125-330-HA | K30: 18.5 | L30: 4P | M30: =INDEX('WEG Motor'!$B$3:$AZ$55, MATCH(K30,'WEG Motor'!$A$3:$A$55,0), MATCH(L30,'WEG Motor'!$B$2:$AZ$2,0))% -> 0.926 | N30: 0.92 | O30: 0.8096 | P30: 4 | Q30: =ROUNDUP(H30/(C26/10^3),2) -> 348.4 | U30: =R26*(C26/10^3) -> 18.846 | Z30: 1 | AA30: 3.517 | AC30: Rated Tonnage =( (Flowrate / 1000) * Density * Change in Temp * Specific Heat) / 3.517
D31: =IFERROR(ROUNDUP((U31*$X$3*1000*$X$4*$X$2)/((C26/10^3)*$X$5*$AA$4),2),"") -> 24.62 | E31: 24.5 | F31: =((($X$5*$AA$4*(C26*0.001)*E31)/1000)/O31) -> 16.02739 | G31: =F31/M31 -> 17.308196 | H31: =G31/N31 -> 18.813257 | I31: SCP-V | J31: SCPV-125-330-HA | K31: 18.5 | L31: 4P | M31: =INDEX('WEG Motor'!$B$3:$AZ$55, MATCH(K31,'WEG Motor'!$A$3:$A$55,0), MATCH(L31,'WEG Motor'!$B$2:$AZ$2,0))% -> 0.926 | N31: 0.92 | O31: 0.8096 | P31: 4 | Q31: =ROUNDUP(H31/(C26/10^3),2) -> 348.4 | U31: =R26*(C26/10^3) -> 18.846
A32: 5 | B32: 500 | C32: =ROUND((B32 * $AA$6 * 1000) / ($X$5*$AA$2*$AA$3),0) -> 60 | D32: =IFERROR(ROUNDUP((U32*$X$3*1000*$X$4*$X$2)/((C32/10^3)*$X$5*$AA$4),2),"") -> 24.62 | E32: 24.5 | F32: =((($X$5*$AA$4*(C32*0.001)*E32)/1000)/O32) -> 17.173946 | G32: =F32/M32 -> 18.446773 | H32: =G32/N32 -> 20.05084 | I32: GIGA-I | J32: Atmos GIGA-I 150/250-22/4-L1 EN | K32: 22 | L32: 4P | M32: =INDEX('WEG Motor'!$B$3:$AZ$55, MATCH(K32,'WEG Motor'!$A$3:$A$55,0), MATCH(L32,'WEG Motor'!$B$2:$AZ$2,0))% -> 0.931 | N32: 0.92 | O32: 0.8395 | P32: 2.507 | Q32: =ROUNDUP(H32/(C32/10^3),2) -> 334.19 | R32: 349 | U32: =R32*(C32/10^3) -> 20.94 | W32: VSD | X32: 0.92 | Z32: △T | AA32: 7 | AC32: Rated Tonnage = Amount if heat needed to melt 1 ton of ice in 24 hrs
D33: =IFERROR(ROUNDUP((U33*$X$3*1000*$X$4*$X$2)/((C32/10^3)*$X$5*$AA$4),2),"") -> 24.62 | E33: 25 | F33: =((($X$5*$AA$4*(C32*0.001)*E33)/1000)/O33) -> 17.733562 | G33: =F33/M33 -> 19.047864 | H33: =G33/N33 -> 20.7042 | I33: GIGA-B | J33: Atmos GIGA-B 125/285-22/4-L1 | K33: 22 | L33: 4P | M33: =INDEX('WEG Motor'!$B$3:$AZ$55, MATCH(K33,'WEG Motor'!$A$3:$A$55,0), MATCH(L33,'WEG Motor'!$B$2:$AZ$2,0))% -> 0.931 | N33: 0.92 | O33: 0.8296 | P33: 2.507 | Q33: =ROUNDUP(H33/(C32/10^3),2) -> 345.08 | U33: =R32*(C32/10^3) -> 20.94 | W33: Motor | X33: 0.94 | Z33: Specific Heat | AA33: 4.186
D34: =IFERROR(ROUNDUP((U34*$X$3*1000*$X$4*$X$2)/((C32/10^3)*$X$5*$AA$4),2),"") -> 24.62 | E34: 25 | F34: =((($X$5*$AA$4*(C32*0.001)*E34)/1000)/O34) -> 17.733562 | G34: =F34/M34 -> 19.047864 | H34: =G34/N34 -> 20.7042 | I34: GIGA-N | J34: Atmos GIGA-N 125/315-22/4-L1 | K34: 22 | L34: 4P | M34: =INDEX('WEG Motor'!$B$3:$AZ$55, MATCH(K34,'WEG Motor'!$A$3:$A$55,0), MATCH(L34,'WEG Motor'!$B$2:$AZ$2,0))% -> 0.931 | N34: 0.92 | O34: 0.8296 | P34: 2.507 | Q34: =ROUNDUP(H34/(C32/10^3),2) -> 345.08 | U34: =R32*(C32/10^3) -> 20.94 | W34: Pump | X34: 0.8 | Z34: g | AA34: 9.81 | AC34: Pump Power limitation = Motor Input / Flowrate [m3/s]
D35: =IFERROR(ROUNDUP((U35*$X$3*1000*$X$4*$X$2)/((C32/10^3)*$X$5*$AA$4),2),"") -> 24.62 | E35: 24.5 | F35: =((($X$5*$AA$4*(C32*0.001)*E35)/1000)/O35) -> 17.173946 | G35: =F35/M35 -> 18.446773 | H35: =G35/N35 -> 20.05084 | I35: GIGA-IC | J35: Atmos GIGA-IC 150/250-22/4-L1-GB3 | K35: 22 | L35: 4P | M35: =INDEX('WEG Motor'!$B$3:$AZ$55, MATCH(K35,'WEG Motor'!$A$3:$A$55,0), MATCH(L35,'WEG Motor'!$B$2:$AZ$2,0))% -> 0.931 | N35: 0.92 | O35: 0.8395 | P35: 3.024 | Q35: =ROUNDUP(H35/(C32/10^3),2) -> 334.19 | U35: =R32*(C32/10^3) -> 20.94 | W35: Density | X35: 999.78 | Z35: RT | AA35: kW
D36: =IFERROR(ROUNDUP((U36*$X$3*1000*$X$4*$X$2)/((C32/10^3)*$X$5*$AA$4),2),"") -> 24.62 | E36: 25 | F36: =((($X$5*$AA$4*(C32*0.001)*E36)/1000)/O36) -> 17.701555 | G36: =F36/M36 -> 19.013486 | H36: =G36/N36 -> 20.666833 | I36: SCP | J36: SCP-125-330-HA | K36: 22 | L36: 4P | M36: =INDEX('WEG Motor'!$B$3:$AZ$55, MATCH(K36,'WEG Motor'!$A$3:$A$55,0), MATCH(L36,'WEG Motor'!$B$2:$AZ$2,0))% -> 0.931 | N36: 0.92 | O36: 0.8311 | P36: 3.93 | Q36: =ROUNDUP(H36/(C32/10^3),2) -> 344.45 | U36: =R32*(C32/10^3) -> 20.94 | Z36: 1 | AA36: 3.517 | AC36: Rated Tonnage =( (Flowrate / 1000) * Density * Change in Temp * Specific Heat) / 3.517
D37: =IFERROR(ROUNDUP((U37*$X$3*1000*$X$4*$X$2)/((C32/10^3)*$X$5*$AA$4),2),"") -> 24.62 | E37: 25 | F37: =((($X$5*$AA$4*(C32*0.001)*E37)/1000)/O37) -> 17.701555 | G37: =F37/M37 -> 19.013486 | H37: =G37/N37 -> 20.666833 | I37: SCP-V | J37: SCPV-125-330-HA | K37: 22 | L37: 4P | M37: =INDEX('WEG Motor'!$B$3:$AZ$55, MATCH(K37,'WEG Motor'!$A$3:$A$55,0), MATCH(L37,'WEG Motor'!$B$2:$AZ$2,0))% -> 0.931 | N37: 0.92 | O37: 0.8311 | P37: 3.93 | Q37: =ROUNDUP(H37/(C32/10^3),2) -> 344.45 | U37: =R32*(C32/10^3) -> 20.94
A38: 6 | B38: 550 | C38: =ROUND((B38 * $AA$6 * 1000) / ($X$5*$AA$2*$AA$3),0) -> 66 | D38: =IFERROR(ROUNDUP((U38*$X$3*1000*$X$4*$X$2)/((C38/10^3)*$X$5*$AA$4),2),"") -> 24.62 | E38: 25.5 | F38: =((($X$5*$AA$4*(C38*0.001)*E38)/1000)/O38) -> 19.474514 | G38: =F38/M38 -> 20.917845 | H38: =G38/N38 -> 22.736788 | I38: GIGA-I | J38: Atmos GIGA-I 150/285-22/4-L1 EN | K38: 22 | L38: 4P | M38: =INDEX('WEG Motor'!$B$3:$AZ$55, MATCH(K38,'WEG Motor'!$A$3:$A$55,0), MATCH(L38,'WEG Motor'!$B$2:$AZ$2,0))% -> 0.931 | N38: 0.92 | O38: 0.8476 | P38: 2.53 | Q38: =ROUNDUP(H38/(C38/10^3),2) -> 344.5 | R38: 349 | U38: =R38*(C38/10^3) -> 23.034 | W38: VSD | X38: 0.92 | Z38: △T | AA38: 7 | AC38: Rated Tonnage = Amount if heat needed to melt 1 ton of ice in 24 hrs
D39: =IFERROR(ROUNDUP((U39*$X$3*1000*$X$4*$X$2)/((C38/10^3)*$X$5*$AA$4),2),"") -> 24.62 | E39: 25 | F39: =((($X$5*$AA$4*(C38*0.001)*E39)/1000)/O39) -> 19.427298 | G39: =F39/M39 -> 20.86713 | H39: =G39/N39 -> 22.681663 | I39: GIGA-B | J39: Atmos GIGA-B 125/285-22/4-L1 | K39: 22 | L39: 4P | M39: =INDEX('WEG Motor'!$B$3:$AZ$55, MATCH(K39,'WEG Motor'!$A$3:$A$55,0), MATCH(L39,'WEG Motor'!$B$2:$AZ$2,0))% -> 0.931 | N39: 0.92 | O39: 0.833 | P39: 2.582 | Q39: =ROUNDUP(H39/(C38/10^3),2) -> 343.67 | U39: =R38*(C38/10^3) -> 23.034 | W39: Motor | X39: 0.94 | Z39: Specific Heat | AA39: 4.186
D40: =IFERROR(ROUNDUP((U40*$X$3*1000*$X$4*$X$2)/((C38/10^3)*$X$5*$AA$4),2),"") -> 24.62 | E40: 24.5 | F40: =((($X$5*$AA$4*(C38*0.001)*E40)/1000)/O40) -> 18.947766 | G40: =F40/M40 -> 20.352058 | H40: =G40/N40 -> 22.121802 | I40: GIGA-N | J40: Atmos GIGA-N 100/160-22/2-L1 | K40: 22 | L40: 4P | M40: =INDEX('WEG Motor'!$B$3:$AZ$55, MATCH(K40,'WEG Motor'!$A$3:$A$55,0), MATCH(L40,'WEG Motor'!$B$2:$AZ$2,0))% -> 0.931 | N40: 0.92 | O40: 0.837 | P40: 4.966 | Q40: =ROUNDUP(H40/(C38/10^3),2) -> 335.18 | U40: =R38*(C38/10^3) -> 23.034 | W40: Pump | X40: 0.8 | Z40: g | AA40: 9.81 | AC40: Pump Power limitation = Motor Input / Flowrate [m3/s]
...

Sheet Condenser Water Pump (301)
A1: S/N | B1: Rated Tonnage | C1: Flowrate (l/s) | D1: Head (m, calculation) | E1: Head (m, datasheet) | F1: Rated Power (kW, P2) | G1: Motor Input (kW, P1) (Pump + Motor) | H1: Overall Power Input (Pump + Motor + VSD) | I1: Pump Model | J1: Pump Model | K1: Motor Size (kW) | L1: Poles | M1: Motor Eff | N1: VSD Eff | O1: Pump Eff | P1: NPSHR (m) | Q1: Pump Power Limitation (kW/m3/s) | R1: SS553 Power Limitation (kW/m3/s) | S1: Price | T1: Remarks | U1: Motor Input (Calculation)
A2: 0 | C2: =ROUND((B2 * $AA$6 * 1000) / ($X$5*$AA$2*$AA$3), 0) -> 0 | D2: =IFERROR(ROUNDUP((U2*$X$3*1000*$X$4*$X$2)/((C2/10^3)*$X$5*$AA$4),2),"") | F2: =((($X$5*$AA$4*(C2*0.001)*E2)/1000)/O2) -> #DIV/0! | G2: =F2/M2 -> #DIV/0! | H2: =G2/N2 -> #DIV/0! | I2: GIGA-I | M2: =INDEX('WEG Motor'!$B$3:$AZ$55, MATCH(K2,'WEG Motor'!$A$3:$A$55,0), MATCH(L2,'WEG Motor'!$B$2:$AZ$2,0))% -> #N/A | N2: 0.92 | Q2: =ROUNDUP(H2/(C2/10^3),2) -> #DIV/0! | R2: 301 | U2: =R2*(C2/10^3) -> 0 | W2: VSD | X2: 0.92 | Z2: △T | AA2: 7 | AC2: Rated Tonnage = Amount if heat needed to melt 1 ton of ice in 24 hrs
D3: =IFERROR(ROUNDUP((U3*$X$3*1000*$X$4*$X$2)/((C2/10^3)*$X$5*$AA$4),2),"") | F3: =((($X$5*$AA$4*(C2*0.001)*E3)/1000)/O3) -> #DIV/0! | G3: =F3/M3 -> #DIV/0! | H3: =G3/N3 -> #DIV/0! | I3: GIGA-B | M3: =INDEX('WEG Motor'!$B$3:$AZ$55, MATCH(K3,'WEG Motor'!$A$3:$A$55,0), MATCH(L3,'WEG Motor'!$B$2:$AZ$2,0))% -> #N/A | N3: 0.92 | Q3: =ROUNDUP(H3/(C2/10^3),2) -> #DIV/0! | U3: =R2*(C2/10^3) -> 0 | W3: Motor | X3: 0.94 | Z3: Specific Heat | AA3: 4.186
D4: =IFERROR(ROUNDUP((U4*$X$3*1000*$X$4*$X$2)/((C2/10^3)*$X$5*$AA$4),2),"") | F4: =((($X$5*$AA$4*(C2*0.001)*E4)/1000)/O4) -> #DIV/0! | G4: =F4/M4 -> #DIV/0! | H4: =G4/N4 -> #DIV/0! | I4: GIGA-N | M4: =INDEX('WEG Motor'!$B$3:$AZ$55, MATCH(K4,'WEG Motor'!$A$3:$A$55,0), MATCH(L4,'WEG Motor'!$B$2:$AZ$2,0))% -> #N/A | N4: 0.92 | Q4: =ROUNDUP(H4/(C2/10^3),2) -> #DIV/0! | U4: =R2*(C2/10^3) -> 0 | W4: Pump | X4: 0.8 | Z4: g | AA4: 9.81 | AC4: Pump Power limitation = Motor Input / Flowrate [m3/s]
D5: =IFERROR(ROUNDUP((U5*$X$3*1000*$X$4*$X$2)/((C2/10^3)*$X$5*$AA$4),2),"") | F5: =((($X$5*$AA$4*(C2*0.001)*E5)/1000)/O5) -> #DIV/0! | G5: =F5/M5 -> #DIV/0! | H5: =G5/N5 -> #DIV/0! | I5: GIGA-IC | M5: =INDEX('WEG Motor'!$B$3:$AZ$55, MATCH(K5,'WEG Motor'!$A$3:$A$55,0), MATCH(L5,'WEG Motor'!$B$2:$AZ$2,0))% -> #N/A | N5: 0.92 | Q5: =ROUNDUP(H5/(C2/10^3),2) -> #DIV/0! | U5: =R2*(C2/10^3) -> 0 | W5: Density | X5: 999.78 | Z5: RT | AA5: kW
D6: =IFERROR(ROUNDUP((U6*$X$3*1000*$X$4*$X$2)/((C2/10^3)*$X$5*$AA$4),2),"") | F6: =((($X$5*$AA$4*(C2*0.001)*E6)/1000)/O6) -> #DIV/0! | G6: =F6/M6 -> #DIV/0! | H6: =G6/N6 -> #DIV/0! | I6: SCP | M6: =INDEX('WEG Motor'!$B$3:$AZ$55, MATCH(K6,'WEG Motor'!$A$3:$A$55,0), MATCH(L6,'WEG Motor'!$B$2:$AZ$2,0))% -> #N/A | N6: 0.92 | Q6: =ROUNDUP(H6/(C2/10^3),2) -> #DIV/0! | U6: =R2*(C2/10^3) -> 0 | Z6: 1 | AA6: 3.517 | AC6: Rated Tonnage =( (Flowrate / 1000) * Density * Change in Temp * Specific Heat) / 3.517
D7: =IFERROR(ROUNDUP((U7*$X$3*1000*$X$4*$X$2)/((C2/10^3)*$X$5*$AA$4),2),"") | F7: =((($X$5*$AA$4*(C2*0.001)*E7)/1000)/O7) -> #DIV/0! | G7: =F7/M7 -> #DIV/0! | H7: =G7/N7 -> #DIV/0! | I7: SCP-V | M7: =INDEX('WEG Motor'!$B$3:$AZ$55, MATCH(K7,'WEG Motor'!$A$3:$A$55,0), MATCH(L7,'WEG Motor'!$B$2:$AZ$2,0))% -> #N/A | N7: 0.92 | Q7: =ROUNDUP(H7/(C2/10^3),2) -> #DIV/0! | U7: =R2*(C2/10^3) -> 0
A8: 1 | B8: 300 | C8: =ROUND((B8 * $AA$6 * 1000) / ($X$5*$AA$2*$AA$3), 0) -> 36 | D8: =IFERROR(ROUNDUP((U8*$X$3*1000*$X$4*$X$2)/((C8/10^3)*$X$5*$AA$4),2),"") -> 21.24 | E8: 20.5 | F8: =((($X$5*$AA$4*(C8*0.001)*E8)/1000)/O8) -> 8.9217148 | G8: =F8/M8 -> 9.761176 | H8: =G8/N8 -> 10.609974 | I8: GIGA-I | J8: Atmos GIGA-I 125/240-11/4-L1 EN | K8: 11 | L8: 4P | M8: =INDEX('WEG Motor'!$B$3:$AZ$55, MATCH(K8,'WEG Motor'!$A$3:$A$55,0), MATCH(L8,'WEG Motor'!$B$2:$AZ$2,0))% -> 0.914 | N8: 0.92 | O8: 0.8113 | P8: 1.726 | Q8: =ROUNDUP(H8/(C8/10^3),2) -> 294.73 | R8: 301 | U8: =R8*(C8/10^3) -> 10.836 | W8: VSD | X8: 0.92 | Z8: △T | AA8: 7 | AC8: Rated Tonnage = Amount if heat needed to melt 1 ton of ice in 24 hrs
D9: =IFERROR(ROUNDUP((U9*$X$3*1000*$X$4*$X$2)/((C8/10^3)*$X$5*$AA$4),2),"") -> 21.24 | E9: 21 | F9: =((($X$5*$AA$4*(C8*0.001)*E9)/1000)/O9) -> 8.9398703 | G9: =F9/M9 -> 9.7810397 | H9: =G9/N9 -> 10.631565 | I9: GIGA-B | J9: Atmos GIGA-B 100/240-11/4-L1 | K9: 11 | L9: 4P | M9: =INDEX('WEG Motor'!$B$3:$AZ$55, MATCH(K9,'WEG Motor'!$A$3:$A$55,0), MATCH(L9,'WEG Motor'!$B$2:$AZ$2,0))% -> 0.914 | N9: 0.92 | O9: 0.8294 | P9: 1.865 | Q9: =ROUNDUP(H9/(C8/10^3),2) -> 295.33 | U9: =R8*(C8/10^3) -> 10.836 | W9: Motor | X9: 0.94 | Z9: Specific Heat | AA9: 4.186
D10: =IFERROR(ROUNDUP((U10*$X$3*1000*$X$4*$X$2)/((C8/10^3)*$X$5*$AA$4),2),"") -> 21.24 | E10: 21 | F10: =((($X$5*$AA$4*(C8*0.001)*E10)/1000)/O10) -> 8.9398703 | G10: =F10/M10 -> 9.7810397 | H10: =G10/N10 -> 10.631565 | I10: GIGA-N | J10: Atmos GIGA-N 100/250-11/4-L1 | K10: 11 | L10: 4P | M10: =INDEX('WEG Motor'!$B$3:$AZ$55, MATCH(K10,'WEG Motor'!$A$3:$A$55,0), MATCH(L10,'WEG Motor'!$B$2:$AZ$2,0))% -> 0.914 | N10: 0.92 | O10: 0.8294 | P10: 1.865 | Q10: =ROUNDUP(H10/(C8/10^3),2) -> 295.33 | U10: =R8*(C8/10^3) -> 10.836 | W10: Pump | X10: 0.8 | Z10: g | AA10: 9.81 | AC10: Pump Power limitation = Motor Input / Flowrate [m3/s]
D11: =IFERROR(ROUNDUP((U11*$X$3*1000*$X$4*$X$2)/((C8/10^3)*$X$5*$AA$4),2),"") -> 21.24 | E11: 20.5 | F11: =((($X$5*$AA$4*(C8*0.001)*E11)/1000)/O11) -> 8.9217148 | G11: =F11/M11 -> 9.761176 | H11: =G11/N11 -> 10.609974 | I11: GIGA-IC | J11: Atmos GIGA-IC 125/250-11/4-L1-GB3 | K11: 11 | L11: 4P | M11: =INDEX('WEG Motor'!$B$3:$AZ$55, MATCH(K11,'WEG Motor'!$A$3:$A$55,0), MATCH(L11,'WEG Motor'!$B$2:$AZ$2,0))% -> 0.914 | N11: 0.92 | O11: 0.8113 | P11: 1.727 | Q11: =ROUNDUP(H11/(C8/10^3),2) -> 294.73 | U11: =R8*(C8/10^3) -> 10.836 | W11: Density | X11: 999.78 | Z11: RT | AA11: kW
D12: =IFERROR(ROUNDUP((U12*$X$3*1000*$X$4*$X$2)/((C8/10^3)*$X$5*$AA$4),2),"") -> 21.24 | E12: 21.5 | F12: =((($X$5*$AA$4*(C8*0.001)*E12)/1000)/O12) -> 8.949858 | G12: =F12/M12 -> 9.7919672 | H12: =G12/N12 -> 10.643443 | I12: SCP | J12: SCP-100-280-HA | K12: 11 | L12: 4P | M12: =INDEX('WEG Motor'!$B$3:$AZ$55, MATCH(K12,'WEG Motor'!$A$3:$A$55,0), MATCH(L12,'WEG Motor'!$B$2:$AZ$2,0))% -> 0.914 | N12: 0.92 | O12: 0.8482 | P12: 2.88 | Q12: =ROUNDUP(H12/(C8/10^3),2) -> 295.66 | U12: =R8*(C8/10^3) -> 10.836 | Z12: 1 | AA12: 3.517 | AC12: Rated Tonnage =( (Flowrate / 1000) * Density * Change in Temp * Specific Heat) / 3.517
D13: =IFERROR(ROUNDUP((U13*$X$3*1000*$X$4*$X$2)/((C8/10^3)*$X$5*$AA$4),2),"") -> 21.24 | E13: 21.5 | F13: =((($X$5*$AA$4*(C8*0.001)*E13)/1000)/O13) -> 8.949858 | G13: =F13/M13 -> 9.7919672 | H13: =G13/N13 -> 10.643443 | I13: SCP-V | J13: SCPV-100-280-HA | K13: 11 | L13: 4P | M13: =INDEX('WEG Motor'!$B$3:$AZ$55, MATCH(K13,'WEG Motor'!$A$3:$A$55,0), MATCH(L13,'WEG Motor'!$B$2:$AZ$2,0))% -> 0.914 | N13: 0.92 | O13: 0.8482 | P13: 2.88 | Q13: =ROUNDUP(H13/(C8/10^3),2) -> 295.66 | U13: =R8*(C8/10^3) -> 10.836
A14: 2 | B14: 350 | C14: =ROUND((B14 * $AA$6 * 1000) / ($X$5*$AA$2*$AA$3), 0) -> 42 | D14: =IFERROR(ROUNDUP((U14*$X$3*1000*$X$4*$X$2)/((C14/10^3)*$X$5*$AA$4),2),"") -> 21.24 | E14: 21 | F14: =((($X$5*$AA$4*(C14*0.001)*E14)/1000)/O14) -> 10.527585 | G14: =F14/M14 -> 11.430602 | H14: =G14/N14 -> 12.424568 | I14: GIGA-I | J14: Atmos GIGA-I 125/250-15/4-L1 EN | K14: 15 | L14: 4P | M14: =INDEX('WEG Motor'!$B$3:$AZ$55, MATCH(K14,'WEG Motor'!$A$3:$A$55,0), MATCH(L14,'WEG Motor'!$B$2:$AZ$2,0))% -> 0.921 | N14: 0.92 | O14: 0.8217 | P14: 1.989 | Q14: =ROUNDUP(H14/(C14/10^3),2) -> 295.83 | R14: 301 | U14: =R14*(C14/10^3) -> 12.642 | W14: VSD | X14: 0.92 | Z14: △T | AA14: 7 | AC14: Rated Tonnage = Amount if heat needed to melt 1 ton of ice in 24 hrs
D15: =IFERROR(ROUNDUP((U15*$X$3*1000*$X$4*$X$2)/((C14/10^3)*$X$5*$AA$4),2),"") -> 21.24 | E15: 21 | F15: =((($X$5*$AA$4*(C14*0.001)*E15)/1000)/O15) -> 10.476585 | G15: =F15/M15 -> 11.375228 | H15: =G15/N15 -> 12.364379 | I15: GIGA-B | J15: Atmos GIGA-B 100/250-15/4-L1 | K15: 15 | L15: 4P | M15: =INDEX('WEG Motor'!$B$3:$AZ$55, MATCH(K15,'WEG Motor'!$A$3:$A$55,0), MATCH(L15,'WEG Motor'!$B$2:$AZ$2,0))% -> 0.921 | N15: 0.92 | O15: 0.8257 | P15: 2.032 | Q15: =ROUNDUP(H15/(C14/10^3),2) -> 294.39 | U15: =R14*(C14/10^3) -> 12.642 | W15: Motor | X15: 0.94 | Z15: Specific Heat | AA15: 4.186
D16: =IFERROR(ROUNDUP((U16*$X$3*1000*$X$4*$X$2)/((C14/10^3)*$X$5*$AA$4),2),"") -> 21.24 | E16: 21 | F16: =((($X$5*$AA$4*(C14*0.001)*E16)/1000)/O16) -> 10.476585 | G16: =F16/M16 -> 11.375228 | H16: =G16/N16 -> 12.364379 | I16: GIGA-N | J16: Atmos GIGA-N 100/250-15/4-L1 | K16: 15 | L16: 4P | M16: =INDEX('WEG Motor'!$B$3:$AZ$55, MATCH(K16,'WEG Motor'!$A$3:$A$55,0), MATCH(L16,'WEG Motor'!$B$2:$AZ$2,0))% -> 0.921 | N16: 0.92 | O16: 0.8257 | P16: 2.032 | Q16: =ROUNDUP(H16/(C14/10^3),2) -> 294.39 | U16: =R14*(C14/10^3) -> 12.642 | W16: Pump | X16: 0.8 | Z16: g | AA16: 9.81 | AC16: Pump Power limitation = Motor Input / Flowrate [m3/s]
D17: =IFERROR(ROUNDUP((U17*$X$3*1000*$X$4*$X$2)/((C14/10^3)*$X$5*$AA$4),2),"") -> 21.24 | E17: 21 | F17: =((($X$5*$AA$4*(C14*0.001)*E17)/1000)/O17) -> 10.535278 | G17: =F17/M17 -> 11.438955 | H17: =G17/N17 -> 12.433647 | I17: GIGA-IC | J17: Atmos GIGA-IC 125/250-15/4-L1-GB3 | K17: 15 | L17: 4P | M17: =INDEX('WEG Motor'!$B$3:$AZ$55, MATCH(K17,'WEG Motor'!$A$3:$A$55,0), MATCH(L17,'WEG Motor'!$B$2:$AZ$2,0))% -> 0.921 | N17: 0.92 | O17: 0.8211 | P17: 2.043 | Q17: =ROUNDUP(H17/(C14/10^3),2) -> 296.04 | U17: =R14*(C14/10^3) -> 12.642 | W17: Density | X17: 999.78 | Z17: RT | AA17: kW
D18: =IFERROR(ROUNDUP((U18*$X$3*1000*$X$4*$X$2)/((C14/10^3)*$X$5*$AA$4),2),"") -> 21.24 | E18: 21.5 | F18: =((($X$5*$AA$4*(C14*0.001)*E18)/1000)/O18) -> 10.553481 | G18: =F18/M18 -> 11.45872 | H18: =G18/N18 -> 12.45513 | I18: SCP | J18: SCP-100-280-HA | K18: 15 | L18: 4P | M18: =INDEX('WEG Motor'!$B$3:$AZ$55, MATCH(K18,'WEG Motor'!$A$3:$A$55,0), MATCH(L18,'WEG Motor'!$B$2:$AZ$2,0))% -> 0.921 | N18: 0.92 | O18: 0.8392 | P18: 3.01 | Q18: =ROUNDUP(H18/(C14/10^3),2) -> 296.56 | U18: =R14*(C14/10^3) -> 12.642 | Z18: 1 | AA18: 3.517 | AC18: Rated Tonnage =( (Flowrate / 1000) * Density * Change in Temp * Specific Heat) / 3.517
D19: =IFERROR(ROUNDUP((U19*$X$3*1000*$X$4*$X$2)/((C14/10^3)*$X$5*$AA$4),2),"") -> 21.24 | E19: 21.5 | F19: =((($X$5*$AA$4*(C14*0.001)*E19)/1000)/O19) -> 10.553481 | G19: =F19/M19 -> 11.45872 | H19: =G19/N19 -> 12.45513 | I19: SCP-V | J19: SCPV-100-280-HA | K19: 15 | L19: 4P | M19: =INDEX('WEG Motor'!$B$3:$AZ$55, MATCH(K19,'WEG Motor'!$A$3:$A$55,0), MATCH(L19,'WEG Motor'!$B$2:$AZ$2,0))% -> 0.921 | N19: 0.92 | O19: 0.8392 | P19: 3.01 | Q19: =ROUNDUP(H19/(C14/10^3),2) -> 296.56 | U19: =R14*(C14/10^3) -> 12.642
A20: 3 | B20: 400 | C20: =ROUND((B20 * $AA$6 * 1000) / ($X$5*$AA$2*$AA$3), 0) -> 48 | D20: =IFERROR(ROUNDUP((U20*$X$3*1000*$X$4*$X$2)/((C20/10^3)*$X$5*$AA$4),2),"") -> 21.24 | E20: 21 | F20: =((($X$5*$AA$4*(C20*0.001)*E20)/1000)/O20) -> 12.008143 | G20: =F20/M20 -> 13.038158 | H20: =G20/N20 -> 14.171911 | I20: GIGA-I | J20: Atmos GIGA-I 125/250-15/4-L1 EN | K20: 15 | L20: 4P | M20: =INDEX('WEG Motor'!$B$3:$AZ$55, MATCH(K20,'WEG Motor'!$A$3:$A$55,0), MATCH(L20,'WEG Motor'!$B$2:$AZ$2,0))% -> 0.921 | N20: 0.92 | O20: 0.8233 | P20: 2.403 | Q20: =ROUNDUP(H20/(C20/10^3),2) -> 295.25 | R20: 301 | U20: =R20*(C20/10^3) -> 14.448 | W20: VSD | X20: 0.92 | Z20: △T | AA20: 7 | AC20: Rated Tonnage = Amount if heat needed to melt 1 ton of ice in 24 hrs
D21: =IFERROR(ROUNDUP((U21*$X$3*1000*$X$4*$X$2)/((C20/10^3)*$X$5*$AA$4),2),"") -> 21.24 | E21: 21 | F21: =((($X$5*$AA$4*(C20*0.001)*E21)/1000)/O21) -> 12.230984 | G21: =F21/M21 -> 13.280113 | H21: =G21/N21 -> 14.434906 | I21: GIGA-B | J21: Atmos GIGA-B 125/230-15/4-L1 | K21: 15 | L21: 4P | M21: =INDEX('WEG Motor'!$B$3:$AZ$55, MATCH(K21,'WEG Motor'!$A$3:$A$55,0), MATCH(L21,'WEG Motor'!$B$2:$AZ$2,0))% -> 0.921 | N21: 0.92 | O21: 0.8083 | P21: 2.55 | Q21: =ROUNDUP(H21/(C20/10^3),2) -> 300.73 | U21: =R20*(C20/10^3) -> 14.448 | W21: Motor | X21: 0.94 | Z21: Specific Heat | AA21: 4.186
D22: =IFERROR(ROUNDUP((U22*$X$3*1000*$X$4*$X$2)/((C20/10^3)*$X$5*$AA$4),2),"") -> 21.24 | E22: 21 | F22: =((($X$5*$AA$4*(C20*0.001)*E22)/1000)/O22) -> 12.230984 | G22: =F22/M22 -> 13.280113 | H22: =G22/N22 -> 14.434906 | I22: GIGA-N | J22: Atmos GIGA-N 125/250-15/4-L1 | K22: 15 | L22: 4P | M22: =INDEX('WEG Motor'!$B$3:$AZ$55, MATCH(K22,'WEG Motor'!$A$3:$A$55,0), MATCH(L22,'WEG Motor'!$B$2:$AZ$2,0))% -> 0.921 | N22: 0.92 | O22: 0.8083 | P22: 2.55 | Q22: =ROUNDUP(H22/(C20/10^3),2) -> 300.73 | U22: =R20*(C20/10^3) -> 14.448 | W22: Pump | X22: 0.8 | Z22: g | AA22: 9.81 | AC22: Pump Power limitation = Motor Input / Flowrate [m3/s]
D23: =IFERROR(ROUNDUP((U23*$X$3*1000*$X$4*$X$2)/((C20/10^3)*$X$5*$AA$4),2),"") -> 21.24 | E23: 21 | F23: =((($X$5*$AA$4*(C20*0.001)*E23)/1000)/O23) -> 12.148322 | G23: =F23/M23 -> 13.190361 | H23: =G23/N23 -> 14.337348 | I23: GIGA-IC | J23: Atmos GIGA-IC 150/250-15/4-L1-GB3 | K23: 15 | L23: 4P | M23: =INDEX('WEG Motor'!$B$3:$AZ$55, MATCH(K23,'WEG Motor'!$A$3:$A$55,0), MATCH(L23,'WEG Motor'!$B$2:$AZ$2,0))% -> 0.921 | N23: 0.92 | O23: 0.8138 | P23: 2.972 | Q23: =ROUNDUP(H23/(C20/10^3),2) -> 298.7 | U23: =R20*(C20/10^3) -> 14.448 | W23: Density | X23: 999.78 | Z23: RT | AA23: kW
D24: =IFERROR(ROUNDUP((U24*$X$3*1000*$X$4*$X$2)/((C20/10^3)*$X$5*$AA$4),2),"") -> 21.24 | E24: 21.5 | F24: =((($X$5*$AA$4*(C20*0.001)*E24)/1000)/O24) -> 12.193341 | G24: =F24/M24 -> 13.239242 | H24: =G24/N24 -> 14.39048 | I24: SCP | J24: SCP-125-290-HA | K24: 15 | L24: 4P | M24: =INDEX('WEG Motor'!$B$3:$AZ$55, MATCH(K24,'WEG Motor'!$A$3:$A$55,0), MATCH(L24,'WEG Motor'!$B$2:$AZ$2,0))% -> 0.921 | N24: 0.92 | O24: 0.8301 | P24: 2.86 | Q24: =ROUNDUP(H24/(C20/10^3),2) -> 299.81 | U24: =R20*(C20/10^3) -> 14.448 | Z24: 1 | AA24: 3.517 | AC24: Rated Tonnage =( (Flowrate / 1000) * Density * Change in Temp * Specific Heat) / 3.517
D25: =IFERROR(ROUNDUP((U25*$X$3*1000*$X$4*$X$2)/((C20/10^3)*$X$5*$AA$4),2),"") -> 21.24 | E25: 21.5 | F25: =((($X$5*$AA$4*(C20*0.001)*E25)/1000)/O25) -> 12.193341 | G25: =F25/M25 -> 13.239242 | H25: =G25/N25 -> 14.39048 | I25: SCP-V | J25: SCPV-125-290-HA | K25: 15 | L25: 4P | M25: =INDEX('WEG Motor'!$B$3:$AZ$55, MATCH(K25,'WEG Motor'!$A$3:$A$55,0), MATCH(L25,'WEG Motor'!$B$2:$AZ$2,0))% -> 0.921 | N25: 0.92 | O25: 0.8301 | P25: 2.86 | Q25: =ROUNDUP(H25/(C20/10^3),2) -> 299.81 | U25: =R20*(C20/10^3) -> 14.448
A26: 4 | B26: 450 | C26: =ROUND((B26 * $AA$6 * 1000) / ($X$5*$AA$2*$AA$3), 0) -> 54 | D26: =IFERROR(ROUNDUP((U26*$X$3*1000*$X$4*$X$2)/((C26/10^3)*$X$5*$AA$4),2),"") -> 21.24 | E26: 21.5 | F26: =((($X$5*$AA$4*(C26*0.001)*E26)/1000)/O26) -> 13.554225 | G26: =F26/M26 -> 14.637392 | H26: =G26/N26 -> 15.910209 | I26: GIGA-I | J26: Atmos GIGA-I 150/240-18.5/4-L1 EN | K26: 18.5 | L26: 4P | M26: =INDEX('WEG Motor'!$B$3:$AZ$55, MATCH(K26,'WEG Motor'!$A$3:$A$55,0), MATCH(L26,'WEG Motor'!$B$2:$AZ$2,0))% -> 0.926 | N26: 0.92 | O26: 0.8401 | P26: 2.887 | Q26: =ROUNDUP(H26/(C26/10^3),2) -> 294.64 | R26: 301 | U26: =R26*(C26/10^3) -> 16.254 | W26: VSD | X26: 0.92 | Z26: △T | AA26: 7 | AC26: Rated Tonnage = Amount if heat needed to melt 1 ton of ice in 24 hrs
D27: =IFERROR(ROUNDUP((U27*$X$3*1000*$X$4*$X$2)/((C26/10^3)*$X$5*$AA$4),2),"") -> 21.24 | E27: 21.5 | F27: =((($X$5*$AA$4*(C26*0.001)*E27)/1000)/O27) -> 13.604426 | G27: =F27/M27 -> 14.691604 | H27: =G27/N27 -> 15.969135 | I27: GIGA-B | J27: Atmos GIGA-B 125/240-18.5/4-L1 | K27: 18.5 | L27: 4P | M27: =INDEX('WEG Motor'!$B$3:$AZ$55, MATCH(K27,'WEG Motor'!$A$3:$A$55,0), MATCH(L27,'WEG Motor'!$B$2:$AZ$2,0))% -> 0.926 | N27: 0.92 | O27: 0.837 | P27: 2.569 | Q27: =ROUNDUP(H27/(C26/10^3),2) -> 295.73 | U27: =R26*(C26/10^3) -> 16.254 | W27: Motor | X27: 0.94 | Z27: Specific Heat | AA27: 4.186
D28: =IFERROR(ROUNDUP((U28*$X$3*1000*$X$4*$X$2)/((C26/10^3)*$X$5*$AA$4),2),"") -> 21.24 | E28: 21.5 | F28: =((($X$5*$AA$4*(C26*0.001)*E28)/1000)/O28) -> 13.604426 | G28: =F28/M28 -> 14.691604 | H28: =G28/N28 -> 15.969135 | I28: GIGA-N | J28: Atmos GIGA-N 125/250-18.5/4-L1 | K28: 18.5 | L28: 4P | M28: =INDEX('WEG Motor'!$B$3:$AZ$55, MATCH(K28,'WEG Motor'!$A$3:$A$55,0), MATCH(L28,'WEG Motor'!$B$2:$AZ$2,0))% -> 0.926 | N28: 0.92 | O28: 0.837 | P28: 2.569 | Q28: =ROUNDUP(H28/(C26/10^3),2) -> 295.73 | U28: =R26*(C26/10^3) -> 16.254 | W28: Pump | X28: 0.8 | Z28: g | AA28: 9.81 | AC28: Pump Power limitation = Motor Input / Flowrate [m3/s]
D29: =IFERROR(ROUNDUP((U29*$X$3*1000*$X$4*$X$2)/((C26/10^3)*$X$5*$AA$4),2),"") -> 21.24 | E29: 21.5 | F29: =((($X$5*$AA$4*(C26*0.001)*E29)/1000)/O29) -> 13.643547 | G29: =F29/M29 -> 14.733852 | H29: =G29/N29 -> 16.015057 | I29: GIGA-IC | J29: Atmos GIGA-IC 150/250-18.5/4-L1-GB3 | K29: 18.5 | L29: 4P | M29: =INDEX('WEG Motor'!$B$3:$AZ$55, MATCH(K29,'WEG Motor'!$A$3:$A$55,0), MATCH(L29,'WEG Motor'!$B$2:$AZ$2,0))% -> 0.926 | N29: 0.92 | O29: 0.8346 | P29: 2.985 | Q29: =ROUNDUP(H29/(C26/10^3),2) -> 296.58 | U29: =R26*(C26/10^3) -> 16.254 | W29: Density | X29: 999.78 | Z29: RT | AA29: kW
D30: =IFERROR(ROUNDUP((U30*$X$3*1000*$X$4*$X$2)/((C26/10^3)*$X$5*$AA$4),2),"") -> 21.24 | E30: 21.5 | F30: =((($X$5*$AA$4*(C26*0.001)*E30)/1000)/O30) -> 13.530067 | G30: =F30/M30 -> 14.690626 | H30: =G30/N30 -> 15.968072 | I30: SCP | J30: SCP-125-290-HA | K30: 15 | L30: 4P | M30: =INDEX('WEG Motor'!$B$3:$AZ$55, MATCH(K30,'WEG Motor'!$A$3:$A$55,0), MATCH(L30,'WEG Motor'!$B$2:$AZ$2,0))% -> 0.921 | N30: 0.92 | O30: 0.8416 | P30: 2.94 | Q30: =ROUNDUP(H30/(C26/10^3),2) -> 295.71 | U30: =R26*(C26/10^3) -> 16.254 | Z30: 1 | AA30: 3.517 | AC30: Rated Tonnage =( (Flowrate / 1000) * Density * Change in Temp * Specific Heat) / 3.517
D31: =IFERROR(ROUNDUP((U31*$X$3*1000*$X$4*$X$2)/((C26/10^3)*$X$5*$AA$4),2),"") -> 21.24 | E31: 21.5 | F31: =((($X$5*$AA$4*(C26*0.001)*E31)/1000)/O31) -> 13.530067 | G31: =F31/M31 -> 14.690626 | H31: =G31/N31 -> 15.968072 | I31: SCP-V | J31: SCPV-125-290-HA | K31: 15 | L31: 4P | M31: =INDEX('WEG Motor'!$B$3:$AZ$55, MATCH(K31,'WEG Motor'!$A$3:$A$55,0), MATCH(L31,'WEG Motor'!$B$2:$AZ$2,0))% -> 0.921 | N31: 0.92 | O31: 0.8416 | P31: 2.94 | Q31: =ROUNDUP(H31/(C26/10^3),2) -> 295.71 | U31: =R26*(C26/10^3) -> 16.254
A32: 5 | B32: 500 | C32: =ROUND((B32 * $AA$6 * 1000) / ($X$5*$AA$2*$AA$3), 0) -> 60 | D32: =IFERROR(ROUNDUP((U32*$X$3*1000*$X$4*$X$2)/((C32/10^3)*$X$5*$AA$4),2),"") -> 21.24 | E32: 21.5 | F32: =((($X$5*$AA$4*(C32*0.001)*E32)/1000)/O32) -> 14.895357 | G32: =F32/M32 -> 16.085698 | H32: =G32/N32 -> 17.484455 | I32: GIGA-I | J32: Atmos GIGA-I 150/240-18.5/4-L1 EN | K32: 18.5 | L32: 4P | M32: =INDEX('WEG Motor'!$B$3:$AZ$55, MATCH(K32,'WEG Motor'!$A$3:$A$55,0), MATCH(L32,'WEG Motor'!$B$2:$AZ$2,0))% -> 0.926 | N32: 0.92 | O32: 0.8494 | P32: 3 | Q32: =ROUNDUP(H32/(C32/10^3),2) -> 291.41 | R32: 301 | U32: =R32*(C32/10^3) -> 18.06 | W32: VSD | X32: 0.92 | Z32: △T | AA32: 7 | AC32: Rated Tonnage = Amount if heat needed to melt 1 ton of ice in 24 hrs
D33: =IFERROR(ROUNDUP((U33*$X$3*1000*$X$4*$X$2)/((C32/10^3)*$X$5*$AA$4),2),"") -> 21.24 | E33: 22 | F33: =((($X$5*$AA$4*(C32*0.001)*E33)/1000)/O33) -> 15.067913 | G33: =F33/M33 -> 16.272045 | H33: =G33/N33 -> 17.687005 | I33: GIGA-B | J33: Atmos GIGA-B 125/240-18.5/4-L1 | K33: 18.5 | L33: 4P | M33: =INDEX('WEG Motor'!$B$3:$AZ$55, MATCH(K33,'WEG Motor'!$A$3:$A$55,0), MATCH(L33,'WEG Motor'!$B$2:$AZ$2,0))% -> 0.926 | N33: 0.92 | O33: 0.8592 | P33: 2.602 | Q33: =ROUNDUP(H33/(C32/10^3),2) -> 294.79 | U33: =R32*(C32/10^3) -> 18.06 | W33: Motor | X33: 0.94 | Z33: Specific Heat | AA33: 4.186
D34: =IFERROR(ROUNDUP((U34*$X$3*1000*$X$4*$X$2)/((C32/10^3)*$X$5*$AA$4),2),"") -> 21.24 | E34: 22 | F34: =((($X$5*$AA$4*(C32*0.001)*E34)/1000)/O34) -> 15.067913 | G34: =F34/M34 -> 16.272045 | H34: =G34/N34 -> 17.687005 | I34: GIGA-N | J34: Atmos GIGA-N 125/250-18.5/4-L1 | K34: 18.5 | L34: 4P | M34: =INDEX('WEG Motor'!$B$3:$AZ$55, MATCH(K34,'WEG Motor'!$A$3:$A$55,0), MATCH(L34,'WEG Motor'!$B$2:$AZ$2,0))% -> 0.926 | N34: 0.92 | O34: 0.8592 | P34: 2.602 | Q34: =ROUNDUP(H34/(C32/10^3),2) -> 294.79 | U34: =R32*(C32/10^3) -> 18.06 | W34: Pump | X34: 0.8 | Z34: g | AA34: 9.81 | AC34: Pump Power limitation = Motor Input / Flowrate [m3/s]
D35: =IFERROR(ROUNDUP((U35*$X$3*1000*$X$4*$X$2)/((C32/10^3)*$X$5*$AA$4),2),"") -> 21.24 | E35: 22 | F35: =((($X$5*$AA$4*(C32*0.001)*E35)/1000)/O35) -> 15.266924 | G35: =F35/M35 -> 16.486958 | H35: =G35/N35 -> 17.920607 | I35: GIGA-IC | J35: Atmos GIGA-IC 150/250-18.5/4-L1-GB3 | K35: 18.5 | L35: 4P | M35: =INDEX('WEG Motor'!$B$3:$AZ$55, MATCH(K35,'WEG Motor'!$A$3:$A$55,0), MATCH(L35,'WEG Motor'!$B$2:$AZ$2,0))% -> 0.926 | N35: 0.92 | O35: 0.848 | P35: 3.027 | Q35: =ROUNDUP(H35/(C32/10^3),2) -> 298.68 | U35: =R32*(C32/10^3) -> 18.06 | W35: Density | X35: 999.78 | Z35: RT | AA35: kW
D36: =IFERROR(ROUNDUP((U36*$X$3*1000*$X$4*$X$2)/((C32/10^3)*$X$5*$AA$4),2),"") -> 21.24 | E36: 22 | F36: =((($X$5*$AA$4*(C32*0.001)*E36)/1000)/O36) -> 15.29217 | G36: =F36/M36 -> 16.514223 | H36: =G36/N36 -> 17.950242 | I36: SCP | J36: SCP-125-290-HA | K36: 18.5 | L36: 4P | M36: =INDEX('WEG Motor'!$B$3:$AZ$55, MATCH(K36,'WEG Motor'!$A$3:$A$55,0), MATCH(L36,'WEG Motor'!$B$2:$AZ$2,0))% -> 0.926 | N36: 0.92 | O36: 0.8466 | P36: 3.04 | Q36: =ROUNDUP(H36/(C32/10^3),2) -> 299.18 | T36: Pump offer is running at the maximum impeller size. | U36: =R32*(C32/10^3) -> 18.06 | Z36: 1 | AA36: 3.517 | AC36: Rated Tonnage =( (Flowrate / 1000) * Density * Change in Temp * Specific Heat) / 3.517
D37: =IFERROR(ROUNDUP((U37*$X$3*1000*$X$4*$X$2)/((C32/10^3)*$X$5*$AA$4),2),"") -> 21.24 | E37: 22 | F37: =((($X$5*$AA$4*(C32*0.001)*E37)/1000)/O37) -> 15.29217 | G37: =F37/M37 -> 16.514223 | H37: =G37/N37 -> 17.950242 | I37: SCP-V | J37: SCPV-125-290-HA | K37: 18.5 | L37: 4P | M37: =INDEX('WEG Motor'!$B$3:$AZ$55, MATCH(K37,'WEG Motor'!$A$3:$A$55,0), MATCH(L37,'WEG Motor'!$B$2:$AZ$2,0))% -> 0.926 | N37: 0.92 | O37: 0.8466 | P37: 3.04 | Q37: =ROUNDUP(H37/(C32/10^3),2) -> 299.18 | T37: Pump offer is running at the maximum impeller size. | U37: =R32*(C32/10^3) -> 18.06
A38: 6 | B38: 550 | C38: =ROUND((B38 * $AA$6 * 1000) / ($X$5*$AA$2*$AA$3), 0) -> 66 | D38: =IFERROR(ROUNDUP((U38*$X$3*1000*$X$4*$X$2)/((C38/10^3)*$X$5*$AA$4),2),"") -> 21.24 | E38: 22 | F38: =((($X$5*$AA$4*(C38*0.001)*E38)/1000)/O38) -> 16.775811 | G38: =F38/M38 -> 18.019131 | H38: =G38/N38 -> 19.586012 | I38: GIGA-I | J38: Atmos GIGA-I 150/250-22/4-L1 EN | K38: 22 | L38: 4P | M38: =INDEX('WEG Motor'!$B$3:$AZ$55, MATCH(K38,'WEG Motor'!$A$3:$A$55,0), MATCH(L38,'WEG Motor'!$B$2:$AZ$2,0))% -> 0.931 | N38: 0.92 | O38: 0.8489 | P38: 3.007 | Q38: =ROUNDUP(H38/(C38/10^3),2) -> 296.76 | R38: 301 | U38: =R38*(C38/10^3) -> 19.866 | W38: VSD | X38: 0.92 | Z38: △T | AA38: 7 | AC38: Rated Tonnage = Amount if heat needed to melt 1 ton of ice in 24 hrs
D39: =IFERROR(ROUNDUP((U39*$X$3*1000*$X$4*$X$2)/((C38/10^3)*$X$5*$AA$4),2),"") -> 21.24 | E39: 22.5 | F39: =((($X$5*$AA$4*(C38*0.001)*E39)/1000)/O39) -> 16.849427 | G39: =F39/M39 -> 18.098203 | H39: =G39/N39 -> 19.67196 | I39: GIGA-B | J39: Atmos GIGA-B 125/250-22/4-L1 | K39: 22 | L39: 4P | M39: =INDEX('WEG Motor'!$B$3:$AZ$55, MATCH(K39,'WEG Motor'!$A$3:$A$55,0), MATCH(L39,'WEG Motor'!$B$2:$AZ$2,0))% -> 0.931 | N39: 0.92 | O39: 0.8644 | P39: 2.662 | Q39: =ROUNDUP(H39/(C38/10^3),2) -> 298.07 | U39: =R38*(C38/10^3) -> 19.866 | W39: Motor | X39: 0.94 | Z39: Specific Heat | AA39: 4.186
D40: =IFERROR(ROUNDUP((U40*$X$3*1000*$X$4*$X$2)/((C38/10^3)*$X$5*$AA$4),2),"") -> 21.24 | E40: 22.5 | F40: =((($X$5*$AA$4*(C38*0.001)*E40)/1000)/O40) -> 16.849427 | G40: =F40/M40 -> 18.098203 | H40: =G40/N40 -> 19.67196 | I40: GIGA-N | J40: Atmos GIGA-N 125/250-22/4-L1 | K40: 22 | L40: 4P | M40: =INDEX('WEG Motor'!$B$3:$AZ$55, MATCH(K40,'WEG Motor'!$A$3:$A$55,0), MATCH(L40,'WEG Motor'!$B$2:$AZ$2,0))% -> 0.931 | N40: 0.92 | O40: 0.8644 | P40: 2.662 | Q40: =ROUNDUP(H40/(C38/10^3),2) -> 298.07 | U40: =R38*(C38/10^3) -> 19.866 | W40: Pump | X40: 0.8 | Z40: g | AA40: 9.81 | AC40: Pump Power limitation = Motor Input / Flowrate [m3/s]
...

Sheet Pump Heads Selection
A1: S/N | B1: Rated Tonnage | C1: Flowrate (l/s) | D1: Head (m) | E1: GIGA-I | P1: GIGA-B | AA1: GIGA-N | AL1: GIGA-IC | AW1: SCP | BH1: SCPV
E2: Pump Model | F2: Motor Size | G2: Poles | H2: Motor Eff | I2: VSD Eff | J2: Pump Eff | K2: NPSHR (m) | L2: Rated Power (kW, P2) | M2: Motor Input (kW, P1) (Pump + Motor) | N2: Overall Power Input (Pump + Motor + VSD) | O2: Remarks | P2: Pump Model | Q2: Motor Size | R2: Poles | S2: Motor Eff | T2: VSD Eff | U2: Pump Eff | V2: NPSHR (m) | W2: Rated Power (kW, P2) | X2: Motor Input (kW, P1) (Pump + Motor) | Y2: Overall Power Input (Pump + Motor + VSD) | Z2: Remarks | AA2: Pump Model | AB2: Motor Size | AC2: Poles | AD2: Motor Eff | AE2: VSD Eff | AF2: Pump Eff | AG2: NPSHR (m) | AH2: Rated Power (kW, P2) | AI2: Motor Input (kW, P1) (Pump + Motor) | AJ2: Overall Power Input (Pump + Motor + VSD) | AK2: Remarks | AL2: Pump Model | AM2: Motor Size | AN2: Poles | AO2: Motor Eff | AP2: VSD Eff | AQ2: Pump Eff | AR2: NPSHR (m) | AS2: Rated Power (kW, P2) | AT2: Motor Input (kW, P1) (Pump + Motor) | AU2: Overall Power Input (Pump + Motor + VSD) | AV2: Remarks | AW2: Pump Model | AX2: Motor Size | AY2: Poles | AZ2: Motor Eff | BA2: VSD Eff | BB2: Pump Eff | BC2: NPSHR (m) | BD2: Rated Power (kW, P2) | BE2: Motor Input (kW, P1) (Pump + Motor) | BF2: Overall Power Input (Pump + Motor + VSD) | BG2: Remarks | BH2: Pump Model | BI2: Motor Size | BJ2: Poles | BK2: Motor Eff | BL2: VSD Eff | BM2: Pump Eff | BN2: NPSHR (m) | BO2: Rated Power (kW, P2) | BP2: Motor Input (kW, P1) (Pump + Motor) | BQ2: Overall Power Input (Pump + Motor + VSD) | BR2: Remarks
A3: 0 | C3: =ROUND((B3 * $BW$7 * 1000) / ($BT$6 * $BW$3 * $BW$4), 0) -> 0 | D3: 15 | H3: =INDEX('WEG Motor'!$B$3:$AZ$55, MATCH(F3,'WEG Motor'!$A$3:$A$55,0), MATCH(G3,'WEG Motor'!$B$2:$AZ$2,0))% -> #N/A | I3: 0.92 | L3: =ROUND(((($BT$6*$BW$5*(C3*0.001)*D3)/1000)/J3), 2) -> #DIV/0! | M3: =ROUND((L3/H3),2) -> #DIV/0! | N3: =ROUND((M3/I3), 2) -> #DIV/0! | S3: =INDEX('WEG Motor'!$B$3:$AZ$55, MATCH(Q3,'WEG Motor'!$A$3:$A$55,0), MATCH(R3,'WEG Motor'!$B$2:$AZ$2,0))% -> #N/A | T3: 0.92 | W3: =ROUND(((($BT$6*$BW$5*(C3*0.001)*D3)/1000)/U3), 2) -> #DIV/0! | X3: =ROUND((W3/S3),2) -> #DIV/0! | Y3: =ROUND((X3/T3), 2) -> #DIV/0! | AD3: =INDEX('WEG Motor'!$B$3:$AZ$55, MATCH(AB3,'WEG Motor'!$A$3:$A$55,0), MATCH(AC3,'WEG Motor'!$B$2:$AZ$2,0))% -> #N/A | AE3: 0.92 | AH3: =ROUND(((($BT$6*$BW$5*(C3*0.001)*D3)/1000)/AF3), 2) -> #DIV/0! | AI3: =ROUND((AH3/AD3),2) -> #DIV/0! | AJ3: =ROUND((AI3/AE3), 2) -> #DIV/0! | AO3: =INDEX('WEG Motor'!$B$3:$AZ$55, MATCH(AM3,'WEG Motor'!$A$3:$A$55,0), MATCH(AN3,'WEG Motor'!$B$2:$AZ$2,0))% -> #N/A | AP3: 0.92 | AS3: =ROUND(((($BT$6*$BW$5*(C3*0.001)*D3)/1000)/AQ3), 2) -> #DIV/0! | AT3: =ROUND((AS3/AO3),2) -> #DIV/0! | AU3: =ROUND((AT3/AP3), 2) -> #DIV/0! | AZ3: =INDEX('WEG Motor'!$B$3:$AZ$55, MATCH(AX3,'WEG Motor'!$A$3:$A$55,0), MATCH(AY3,'WEG Motor'!$B$2:$AZ$2,0))% -> #N/A | BA3: 0.92 | BD3: =ROUND(((($BT$6*$BW$5*(C3*0.001)*D3)/1000)/BB3), 2) -> #DIV/0! | BE3: =ROUND((BD3/AZ3),2) -> #DIV/0! | BF3: =ROUND((BE3/BA3), 2) -> #DIV/0! | BK3: =INDEX('WEG Motor'!$B$3:$AZ$55, MATCH(BI3,'WEG Motor'!$A$3:$A$55,0), MATCH(BJ3,'WEG Motor'!$B$2:$AZ$2,0))% -> #N/A | BL3: 0.92 | BO3: =ROUND(((($BT$6*$BW$5*(C3*0.001)*D3)/1000)/BM3), 2) -> #DIV/0! | BP3: =ROUND((BO3/BK3),2) -> #DIV/0! | BQ3: =ROUND((BP3/BL3), 2) -> #DIV/0! | BS3: VSD | BT3: 0.92 | BV3: △T | BW3: 7 | BY3: Rated Tonnage = Amount if heat needed to melt 1 ton of ice in 24 hrs
D4: 20 | H4: =INDEX('WEG Motor'!$B$3:$AZ$55, MATCH(F4,'WEG Motor'!$A$3:$A$55,0), MATCH(G4,'WEG Motor'!$B$2:$AZ$2,0))% -> #N/A | I4: 0.92 | L4: =ROUND(((($BT$6*$BW$5*(C3*0.001)*D4)/1000)/J4), 2) -> #DIV/0! | M4: =ROUND((L4/H4),2) -> #DIV/0! | N4: =ROUND((M4/I4), 2) -> #DIV/0! | S4: =INDEX('WEG Motor'!$B$3:$AZ$55, MATCH(Q4,'WEG Motor'!$A$3:$A$55,0), MATCH(R4,'WEG Motor'!$B$2:$AZ$2,0))% -> #N/A | T4: 0.92 | W4: =ROUND(((($BT$6*$BW$5*(C3*0.001)*D4)/1000)/U4), 2) -> #DIV/0! | X4: =ROUND((W4/S4),2) -> #DIV/0! | Y4: =ROUND((X4/T4), 2) -> #DIV/0! | AD4: =INDEX('WEG Motor'!$B$3:$AZ$55, MATCH(AB4,'WEG Motor'!$A$3:$A$55,0), MATCH(AC4,'WEG Motor'!$B$2:$AZ$2,0))% -> #N/A | AE4: 0.92 | AH4: =ROUND(((($BT$6*$BW$5*(C3*0.001)*D4)/1000)/AF4), 2) -> #DIV/0! | AI4: =ROUND((AH4/AD4),2) -> #DIV/0! | AJ4: =ROUND((AI4/AE4), 2) -> #DIV/0! | AO4: =INDEX('WEG Motor'!$B$3:$AZ$55, MATCH(AM4,'WEG Motor'!$A$3:$A$55,0), MATCH(AN4,'WEG Motor'!$B$2:$AZ$2,0))% -> #N/A | AP4: 0.92 | AS4: =ROUND(((($BT$6*$BW$5*(C3*0.001)*D4)/1000)/AQ4), 2) -> #DIV/0! | AT4: =ROUND((AS4/AO4),2) -> #DIV/0! | AU4: =ROUND((AT4/AP4), 2) -> #DIV/0! | AZ4: =INDEX('WEG Motor'!$B$3:$AZ$55, MATCH(AX4,'WEG Motor'!$A$3:$A$55,0), MATCH(AY4,'WEG Motor'!$B$2:$AZ$2,0))% -> #N/A | BA4: 0.92 | BD4: =ROUND(((($BT$6*$BW$5*(C3*0.001)*D4)/1000)/BB4), 2) -> #DIV/0! | BE4: =ROUND((BD4/AZ4),2) -> #DIV/0! | BF4: =ROUND((BE4/BA4), 2) -> #DIV/0! | BK4: =INDEX('WEG Motor'!$B$3:$AZ$55, MATCH(BI4,'WEG Motor'!$A$3:$A$55,0), MATCH(BJ4,'WEG Motor'!$B$2:$AZ$2,0))% -> #N/A | BL4: 0.92 | BO4: =ROUND(((($BT$6*$BW$5*(C3*0.001)*D4)/1000)/BM4), 2) -> #DIV/0! | BP4: =ROUND((BO4/BK4),2) -> #DIV/0! | BQ4: =ROUND((BP4/BL4), 2) -> #DIV/0! | BS4: Motor | BT4: 0.94 | BV4: Specific Heat | BW4: 4.186
D5: 25 | H5: =INDEX('WEG Motor'!$B$3:$AZ$55, MATCH(F5,'WEG Motor'!$A$3:$A$55,0), MATCH(G5,'WEG Motor'!$B$2:$AZ$2,0))% -> #N/A | I5: 0.92 | L5: =ROUND(((($BT$6*$BW$5*(C3*0.001)*D5)/1000)/J5), 2) -> #DIV/0! | M5: =ROUND((L5/H5),2) -> #DIV/0! | N5: =ROUND((M5/I5), 2) -> #DIV/0! | S5: =INDEX('WEG Motor'!$B$3:$AZ$55, MATCH(Q5,'WEG Motor'!$A$3:$A$55,0), MATCH(R5,'WEG Motor'!$B$2:$AZ$2,0))% -> #N/A | T5: 0.92 | W5: =ROUND(((($BT$6*$BW$5*(C3*0.001)*D5)/1000)/U5), 2) -> #DIV/0! | X5: =ROUND((W5/S5),2) -> #DIV/0! | Y5: =ROUND((X5/T5), 2) -> #DIV/0! | AD5: =INDEX('WEG Motor'!$B$3:$AZ$55, MATCH(AB5,'WEG Motor'!$A$3:$A$55,0), MATCH(AC5,'WEG Motor'!$B$2:$AZ$2,0))% -> #N/A | AE5: 0.92 | AH5: =ROUND(((($BT$6*$BW$5*(C3*0.001)*D5)/1000)/AF5), 2) -> #DIV/0! | AI5: =ROUND((AH5/AD5),2) -> #DIV/0! | AJ5: =ROUND((AI5/AE5), 2) -> #DIV/0! | AO5: =INDEX('WEG Motor'!$B$3:$AZ$55, MATCH(AM5,'WEG Motor'!$A$3:$A$55,0), MATCH(AN5,'WEG Motor'!$B$2:$AZ$2,0))% -> #N/A | AP5: 0.92 | AS5: =ROUND(((($BT$6*$BW$5*(C3*0.001)*D5)/1000)/AQ5), 2) -> #DIV/0! | AT5: =ROUND((AS5/AO5),2) -> #DIV/0! | AU5: =ROUND((AT5/AP5), 2) -> #DIV/0! | AZ5: =INDEX('WEG Motor'!$B$3:$AZ$55, MATCH(AX5,'WEG Motor'!$A$3:$A$55,0), MATCH(AY5,'WEG Motor'!$B$2:$AZ$2,0))% -> #N/A | BA5: 0.92 | BD5: =ROUND(((($BT$6*$BW$5*(C3*0.001)*D5)/1000)/BB5), 2) -> #DIV/0! | BE5: =ROUND((BD5/AZ5),2) -> #DIV/0! | BF5: =ROUND((BE5/BA5), 2) -> #DIV/0! | BK5: =INDEX('WEG Motor'!$B$3:$AZ$55, MATCH(BI5,'WEG Motor'!$A$3:$A$55,0), MATCH(BJ5,'WEG Motor'!$B$2:$AZ$2,0))% -> #N/A | BL5: 0.92 | BO5: =ROUND(((($BT$6*$BW$5*(C3*0.001)*D5)/1000)/BM5), 2) -> #DIV/0! | BP5: =ROUND((BO5/BK5),2) -> #DIV/0! | BQ5: =ROUND((BP5/BL5), 2) -> #DIV/0! | BS5: Pump | BT5: 0.8 | BV5: g | BW5: 9.81 | BY5: Pump Power limitation = Motor Input / Flowrate [m3/s]
D6: 30 | H6: =INDEX('WEG Motor'!$B$3:$AZ$55, MATCH(F6,'WEG Motor'!$A$3:$A$55,0), MATCH(G6,'WEG Motor'!$B$2:$AZ$2,0))% -> #N/A | I6: 0.92 | L6: =ROUND(((($BT$6*$BW$5*(C3*0.001)*D6)/1000)/J6), 2) -> #DIV/0! | M6: =ROUND((L6/H6),2) -> #DIV/0! | N6: =ROUND((M6/I6), 2) -> #DIV/0! | S6: =INDEX('WEG Motor'!$B$3:$AZ$55, MATCH(Q6,'WEG Motor'!$A$3:$A$55,0), MATCH(R6,'WEG Motor'!$B$2:$AZ$2,0))% -> #N/A | T6: 0.92 | W6: =ROUND(((($BT$6*$BW$5*(C3*0.001)*D6)/1000)/U6), 2) -> #DIV/0! | X6: =ROUND((W6/S6),2) -> #DIV/0! | Y6: =ROUND((X6/T6), 2) -> #DIV/0! | AD6: =INDEX('WEG Motor'!$B$3:$AZ$55, MATCH(AB6,'WEG Motor'!$A$3:$A$55,0), MATCH(AC6,'WEG Motor'!$B$2:$AZ$2,0))% -> #N/A | AE6: 0.92 | AH6: =ROUND(((($BT$6*$BW$5*(C3*0.001)*D6)/1000)/AF6), 2) -> #DIV/0! | AI6: =ROUND((AH6/AD6),2) -> #DIV/0! | AJ6: =ROUND((AI6/AE6), 2) -> #DIV/0! | AO6: =INDEX('WEG Motor'!$B$3:$AZ$55, MATCH(AM6,'WEG Motor'!$A$3:$A$55,0), MATCH(AN6,'WEG Motor'!$B$2:$AZ$2,0))% -> #N/A | AP6: 0.92 | AS6: =ROUND(((($BT$6*$BW$5*(C3*0.001)*D6)/1000)/AQ6), 2) -> #DIV/0! | AT6: =ROUND((AS6/AO6),2) -> #DIV/0! | AU6: =ROUND((AT6/AP6), 2) -> #DIV/0! | AZ6: =INDEX('WEG Motor'!$B$3:$AZ$55, MATCH(AX6,'WEG Motor'!$A$3:$A$55,0), MATCH(AY6,'WEG Motor'!$B$2:$AZ$2,0))% -> #N/A | BA6: 0.92 | BD6: =ROUND(((($BT$6*$BW$5*(C3*0.001)*D6)/1000)/BB6), 2) -> #DIV/0! | BE6: =ROUND((BD6/AZ6),2) -> #DIV/0! | BF6: =ROUND((BE6/BA6), 2) -> #DIV/0! | BK6: =INDEX('WEG Motor'!$B$3:$AZ$55, MATCH(BI6,'WEG Motor'!$A$3:$A$55,0), MATCH(BJ6,'WEG Motor'!$B$2:$AZ$2,0))% -> #N/A | BL6: 0.92 | BO6: =ROUND(((($BT$6*$BW$5*(C3*0.001)*D6)/1000)/BM6), 2) -> #DIV/0! | BP6: =ROUND((BO6/BK6),2) -> #DIV/0! | BQ6: =ROUND((BP6/BL6), 2) -> #DIV/0! | BS6: Density | BT6: 999.78 | BV6: RT | BW6: kW
D7: 35 | H7: =INDEX('WEG Motor'!$B$3:$AZ$55, MATCH(F7,'WEG Motor'!$A$3:$A$55,0), MATCH(G7,'WEG Motor'!$B$2:$AZ$2,0))% -> #N/A | I7: 0.92 | L7: =ROUND(((($BT$6*$BW$5*(C7*0.001)*D7)/1000)/J7), 2) -> #DIV/0! | M7: =ROUND((L7/H7),2) -> #DIV/0! | N7: =ROUND((M7/I7), 2) -> #DIV/0! | S7: =INDEX('WEG Motor'!$B$3:$AZ$55, MATCH(Q7,'WEG Motor'!$A$3:$A$55,0), MATCH(R7,'WEG Motor'!$B$2:$AZ$2,0))% -> #N/A | T7: 0.92 | W7: =ROUND(((($BT$6*$BW$5*(C3*0.001)*D7)/1000)/U7), 2) -> #DIV/0! | X7: =ROUND((W7/S7),2) -> #DIV/0! | Y7: =ROUND((X7/T7), 2) -> #DIV/0! | AD7: =INDEX('WEG Motor'!$B$3:$AZ$55, MATCH(AB7,'WEG Motor'!$A$3:$A$55,0), MATCH(AC7,'WEG Motor'!$B$2:$AZ$2,0))% -> #N/A | AE7: 0.92 | AH7: =ROUND(((($BT$6*$BW$5*(C3*0.001)*D7)/1000)/AF7), 2) -> #DIV/0! | AI7: =ROUND((AH7/AD7),2) -> #DIV/0! | AJ7: =ROUND((AI7/AE7), 2) -> #DIV/0! | AO7: =INDEX('WEG Motor'!$B$3:$AZ$55, MATCH(AM7,'WEG Motor'!$A$3:$A$55,0), MATCH(AN7,'WEG Motor'!$B$2:$AZ$2,0))% -> #N/A | AP7: 0.92 | AS7: =ROUND(((($BT$6*$BW$5*(C3*0.001)*D7)/1000)/AQ7), 2) -> #DIV/0! | AT7: =ROUND((AS7/AO7),2) -> #DIV/0! | AU7: =ROUND((AT7/AP7), 2) -> #DIV/0! | AZ7: =INDEX('WEG Motor'!$B$3:$AZ$55, MATCH(AX7,'WEG Motor'!$A$3:$A$55,0), MATCH(AY7,'WEG Motor'!$B$2:$AZ$2,0))% -> #N/A | BA7: 0.92 | BD7: =ROUND(((($BT$6*$BW$5*(C3*0.001)*D7)/1000)/BB7), 2) -> #DIV/0! | BE7: =ROUND((BD7/AZ7),2) -> #DIV/0! | BF7: =ROUND((BE7/BA7), 2) -> #DIV/0! | BK7: =INDEX('WEG Motor'!$B$3:$AZ$55, MATCH(BI7,'WEG Motor'!$A$3:$A$55,0), MATCH(BJ7,'WEG Motor'!$B$2:$AZ$2,0))% -> #N/A | BL7: 0.92 | BO7: =ROUND(((($BT$6*$BW$5*(C3*0.001)*D7)/1000)/BM7), 2) -> #DIV/0! | BP7: =ROUND((BO7/BK7),2) -> #DIV/0! | BQ7: =ROUND((BP7/BL7), 2) -> #DIV/0! | BV7: 1 | BW7: 3.517 | BY7: Rated Tonnage =( (Flowrate / 1000) * Density * Change in Temp * Specific Heat) / 3.517
